Workbook

Sheet Summary
A1: Client Test Cases — Lending and Depository Management
A2: Detailed functional test cases with explicit preconditions, data, steps, and expected results. Statuses are reset for client execution.
A3: OVERNIGHT AUDIT SUMMARY (2026-08-30 18:09:23): 4177 test cases reviewed across 43 sheets | 1 updated | 68 added | 81 scenarios flagged as unverifiable (see 'SCENARIOS NOT VERIFIABLE' sheet).
A5: Module | B5: Area | C5: Test Cases | D5: Automated | E5: Passed | F5: Failed | G5: Not Executed | H5: Blocked
A6: Loan Account | B6: Lending Management | C6: =COUNTA('LME Loan Account'!$B$14:$B$2000) | D6: =COUNTIF('LME Loan Account'!$H$14:$H$2000,"Yes") | E6: =COUNTIF('LME Loan Account'!$I$14:$I$2000,"Passed") | F6: =COUNTIF('LME Loan Account'!$I$14:$I$2000,"Failed") | G6: =COUNTIF('LME Loan Account'!$I$14:$I$2000,"Not Executed") | H6: =COUNTIF('LME Loan Account'!$I$14:$I$2000,"Blocked")
A7: Configuration | B7: Lending Management | C7: =COUNTA('LME Configuration'!$B$14:$B$2000) | D7: =COUNTIF('LME Configuration'!$H$14:$H$2000,"Yes") | E7: =COUNTIF('LME Configuration'!$I$14:$I$2000,"Passed") | F7: =COUNTIF('LME Configuration'!$I$14:$I$2000,"Failed") | G7: =COUNTIF('LME Configuration'!$I$14:$I$2000,"Not Executed") | H7: =COUNTIF('LME Configuration'!$I$14:$I$2000,"Blocked")
A8: Loan Type | B8: Lending Management | C8: =COUNTA('LME Loan Type'!$B$14:$B$2000) | D8: =COUNTIF('LME Loan Type'!$H$14:$H$2000,"Yes") | E8: =COUNTIF('LME Loan Type'!$I$14:$I$2000,"Passed") | F8: =COUNTIF('LME Loan Type'!$I$14:$I$2000,"Failed") | G8: =COUNTIF('LME Loan Type'!$I$14:$I$2000,"Not Executed") | H8: =COUNTIF('LME Loan Type'!$I$14:$I$2000,"Blocked")
A9: Loan Type Standard Automation | B9: Lending Management | C9: =COUNTA('LME Loan Type - Standard'!$B$14:$B$2000) | D9: =COUNTIF('LME Loan Type - Standard'!$H$14:$H$2000,"Yes") | E9: =COUNTIF('LME Loan Type - Standard'!$I$14:$I$2000,"Passed") | F9: =COUNTIF('LME Loan Type - Standard'!$I$14:$I$2000,"Failed") | G9: =COUNTIF('LME Loan Type - Standard'!$I$14:$I$2000,"Not Executed") | H9: =COUNTIF('LME Loan Type - Standard'!$I$14:$I$2000,"Blocked")
A10: Standard Automation Scenarios | B10: Lending Management | C10: =COUNTA('Standard automation scenarios'!$B$14:$B$2000) | D10: =COUNTIF('Standard automation scenarios'!$H$14:$H$2000,"Yes") | E10: =COUNTIF('Standard automation scenarios'!$I$14:$I$2000,"Passed") | F10: =COUNTIF('Standard automation scenarios'!$I$14:$I$2000,"Failed") | G10: =COUNTIF('Standard automation scenarios'!$I$14:$I$2000,"Not Executed") | H10: =COUNTIF('Standard automation scenarios'!$I$14:$I$2000,"Blocked")
A11: Standard Statement Generation and Reversal | B11: Lending Management | C11: =COUNTA('LME Standard Statements'!$B$14:$B$2000) | D11: =COUNTIF('LME Standard Statements'!$H$14:$H$2000,"Yes") | E11: =COUNTIF('LME Standard Statements'!$I$14:$I$2000,"Passed") | F11: =COUNTIF('LME Standard Statements'!$I$14:$I$2000,"Failed") | G11: =COUNTIF('LME Standard Statements'!$I$14:$I$2000,"Not Executed") | H11: =COUNTIF('LME Standard Statements'!$I$14:$I$2000,"Blocked")
A12: Standard Statement Generation & Reversal - Detailed | B12: Lending Management | C12: =COUNTA('LME Std Stmt Gen Rev'!$B$14:$B$2000) | D12: =COUNTIF('LME Std Stmt Gen Rev'!$H$14:$H$2000,"Yes") | E12: =COUNTIF('LME Std Stmt Gen Rev'!$I$14:$I$2000,"Passed") | F12: =COUNTIF('LME Std Stmt Gen Rev'!$I$14:$I$2000,"Failed") | G12: =COUNTIF('LME Std Stmt Gen Rev'!$I$14:$I$2000,"Not Executed") | H12: =COUNTIF('LME Std Stmt Gen Rev'!$I$14:$I$2000,"Blocked")
A13: Loan Interest Rate | B13: Lending Management | C13: =COUNTA('LME Interest Rate'!$B$14:$B$2000) | D13: =COUNTIF('LME Interest Rate'!$H$14:$H$2000,"Yes") | E13: =COUNTIF('LME Interest Rate'!$I$14:$I$2000,"Passed") | F13: =COUNTIF('LME Interest Rate'!$I$14:$I$2000,"Failed") | G13: =COUNTIF('LME Interest Rate'!$I$14:$I$2000,"Not Executed") | H13: =COUNTIF('LME Interest Rate'!$I$14:$I$2000,"Blocked")
A14: Interest Calculation (Monthly) | B14: Lending Management | C14: =COUNTA('LME Interest Calc - Monthly'!$B$14:$B$2000) | D14: =COUNTIF('LME Interest Calc - Monthly'!$H$14:$H$2000,"Yes") | E14: =COUNTIF('LME Interest Calc - Monthly'!$I$14:$I$2000,"Passed") | F14: =COUNTIF('LME Interest Calc - Monthly'!$I$14:$I$2000,"Failed") | G14: =COUNTIF('LME Interest Calc - Monthly'!$I$14:$I$2000,"Not Executed") | H14: =COUNTIF('LME Interest Calc - Monthly'!$I$14:$I$2000,"Blocked")
A15: Interest Calculation (Standard) | B15: Lending Management | C15: =COUNTA('LME Interest Calc - Standard'!$B$14:$B$2000) | D15: =COUNTIF('LME Interest Calc - Standard'!$H$14:$H$2000,"Yes") | E15: =COUNTIF('LME Interest Calc - Standard'!$I$14:$I$2000,"Passed") | F15: =COUNTIF('LME Interest Calc - Standard'!$I$14:$I$2000,"Failed") | G15: =COUNTIF('LME Interest Calc - Standard'!$I$14:$I$2000,"Not Executed") | H15: =COUNTIF('LME Interest Calc - Standard'!$I$14:$I$2000,"Blocked")
A16: Loan Category | B16: Lending Management | C16: =COUNTA('LME Loan Category'!$B$14:$B$1995) | D16: =COUNTIF('LME Loan Category'!$H$14:$H$1995,"Yes") | E16: =COUNTIF('LME Loan Category'!$I$14:$I$1995,"Passed") | F16: =COUNTIF('LME Loan Category'!$I$14:$I$1995,"Failed") | G16: =COUNTIF('LME Loan Category'!$I$14:$I$1995,"Not Executed") | H16: =COUNTIF('LME Loan Category'!$I$14:$I$1995,"Blocked")
A17: Loan Fee Type | B17: Lending Management | C17: =COUNTA('LME Loan Fee Type'!$B$14:$B$2000) | D17: =COUNTIF('LME Loan Fee Type'!$H$14:$H$2000,"Yes") | E17: =COUNTIF('LME Loan Fee Type'!$I$14:$I$2000,"Passed") | F17: =COUNTIF('LME Loan Fee Type'!$I$14:$I$2000,"Failed") | G17: =COUNTIF('LME Loan Fee Type'!$I$14:$I$2000,"Not Executed") | H17: =COUNTIF('LME Loan Fee Type'!$I$14:$I$2000,"Blocked")
A18: Fee Capitalization | B18: Lending Management | C18: =COUNTA('LME Fee Capitalization'!$B$14:$B$2000) | D18: =COUNTIF('LME Fee Capitalization'!$H$14:$H$2000,"Yes") | E18: =COUNTIF('LME Fee Capitalization'!$I$14:$I$2000,"Passed") | F18: =COUNTIF('LME Fee Capitalization'!$I$14:$I$2000,"Failed") | G18: =COUNTIF('LME Fee Capitalization'!$I$14:$I$2000,"Not Executed") | H18: =COUNTIF('LME Fee Capitalization'!$I$14:$I$2000,"Blocked")
A19: Loan Adjustment | B19: Lending Management | C19: =COUNTA('LME Loan Adjustment'!$B$14:$B$2000) | D19: =COUNTIF('LME Loan Adjustment'!$H$14:$H$2000,"Yes") | E19: =COUNTIF('LME Loan Adjustment'!$I$14:$I$2000,"Passed") | F19: =COUNTIF('LME Loan Adjustment'!$I$14:$I$2000,"Failed") | G19: =COUNTIF('LME Loan Adjustment'!$I$14:$I$2000,"Not Executed") | H19: =COUNTIF('LME Loan Adjustment'!$I$14:$I$2000,"Blocked")
A20: Loan Write-Off | B20: Lending Management | C20: =COUNTA('LME Loan Write-Off'!$B$14:$B$2000) | D20: =COUNTIF('LME Loan Write-Off'!$H$14:$H$2000,"Yes") | E20: =COUNTIF('LME Loan Write-Off'!$I$14:$I$2000,"Passed") | F20: =COUNTIF('LME Loan Write-Off'!$I$14:$I$2000,"Failed") | G20: =COUNTIF('LME Loan Write-Off'!$I$14:$I$2000,"Not Executed") | H20: =COUNTIF('LME Loan Write-Off'!$I$14:$I$2000,"Blocked")
A21: Loan Statements | B21: Lending Management | C21: =COUNTA('LME Statements'!$B$14:$B$2000) | D21: =COUNTIF('LME Statements'!$H$14:$H$2000,"Yes") | E21: =COUNTIF('LME Statements'!$I$14:$I$2000,"Passed") | F21: =COUNTIF('LME Statements'!$I$14:$I$2000,"Failed") | G21: =COUNTIF('LME Statements'!$I$14:$I$2000,"Not Executed") | H21: =COUNTIF('LME Statements'!$I$14:$I$2000,"Blocked")
A22: Interest and Statement Periods Workflow | B22: Lending Management | C22: =COUNTA('LME Interest and Stmt Runs'!$B$14:$B$2000) | D22: =COUNTIF('LME Interest and Stmt Runs'!$H$14:$H$2000,"Yes") | E22: =COUNTIF('LME Interest and Stmt Runs'!$I$14:$I$2000,"Passed") | F22: =COUNTIF('LME Interest and Stmt Runs'!$I$14:$I$2000,"Failed") | G22: =COUNTIF('LME Interest and Stmt Runs'!$I$14:$I$2000,"Not Executed") | H22: =COUNTIF('LME Interest and Stmt Runs'!$I$14:$I$2000,"Blocked")
A23: Loan Ledger Report | B23: Lending Management | C23: =COUNTA('LME Ledger Report'!$B$14:$B$2000) | D23: =COUNTIF('LME Ledger Report'!$H$14:$H$2000,"Yes") | E23: =COUNTIF('LME Ledger Report'!$I$14:$I$2000,"Passed") | F23: =COUNTIF('LME Ledger Report'!$I$14:$I$2000,"Failed") | G23: =COUNTIF('LME Ledger Report'!$I$14:$I$2000,"Not Executed") | H23: =COUNTIF('LME Ledger Report'!$I$14:$I$2000,"Blocked")
A24: Roll Forward Report | B24: Lending Management | C24: =COUNTA('LME Roll Forward'!$B$14:$B$2000) | D24: =COUNTIF('LME Roll Forward'!$H$14:$H$2000,"Yes") | E24: =COUNTIF('LME Roll Forward'!$I$14:$I$2000,"Passed") | F24: =COUNTIF('LME Roll Forward'!$I$14:$I$2000,"Failed") | G24: =COUNTIF('LME Roll Forward'!$I$14:$I$2000,"Not Executed") | H24: =COUNTIF('LME Roll Forward'!$I$14:$I$2000,"Blocked")
A25: Loan Payment | B25: Lending Management | C25: =COUNTA('LME Loan Payment from depositor'!$B$14:$B$2000) | D25: =COUNTIF('LME Loan Payment from depositor'!$H$14:$H$2000,"Yes") | E25: =COUNTIF('LME Loan Payment from depositor'!$I$14:$I$2000,"Passed") | F25: =COUNTIF('LME Loan Payment from depositor'!$I$14:$I$2000,"Failed") | G25: =COUNTIF('LME Loan Payment from depositor'!$I$14:$I$2000,"Not Executed") | H25: =COUNTIF('LME Loan Payment from depositor'!$I$14:$I$2000,"Blocked")
A26: Overpayment | B26: Lending Management | C26: =COUNTA('LME Overpayment'!$B$14:$B$2000) | D26: =COUNTIF('LME Overpayment'!$H$14:$H$2000,"Yes") | E26: =COUNTIF('LME Overpayment'!$I$14:$I$2000,"Passed") | F26: =COUNTIF('LME Overpayment'!$I$14:$I$2000,"Failed") | G26: =COUNTIF('LME Overpayment'!$I$14:$I$2000,"Not Executed") | H26: =COUNTIF('LME Overpayment'!$I$14:$I$2000,"Blocked")
A27: Loan Invoice UI | B27: Lending Management | C27: =COUNTA('LME Invoice UI'!$B$14:$B$2000) | D27: =COUNTIF('LME Invoice UI'!$H$14:$H$2000,"Yes") | E27: =COUNTIF('LME Invoice UI'!$I$14:$I$2000,"Passed") | F27: =COUNTIF('LME Invoice UI'!$I$14:$I$2000,"Failed") | G27: =COUNTIF('LME Invoice UI'!$I$14:$I$2000,"Not Executed") | H27: =COUNTIF('LME Invoice UI'!$I$14:$I$2000,"Blocked")
A28: AR Payment | B28: Lending Management | C28: =COUNTA('LME AR Payment'!$B$14:$B$2000) | D28: =COUNTIF('LME AR Payment'!$H$14:$H$2000,"Yes") | E28: =COUNTIF('LME AR Payment'!$I$14:$I$2000,"Passed") | F28: =COUNTIF('LME AR Payment'!$I$14:$I$2000,"Failed") | G28: =COUNTIF('LME AR Payment'!$I$14:$I$2000,"Not Executed") | H28: =COUNTIF('LME AR Payment'!$I$14:$I$2000,"Blocked")
A29: Payment & Payoff | B29: Lending Management | C29: =COUNTA('LME Payment & Payoff'!$B$14:$B$2000) | D29: =COUNTIF('LME Payment & Payoff'!$H$14:$H$2000,"Yes") | E29: =COUNTIF('LME Payment & Payoff'!$I$14:$I$2000,"Passed") | F29: =COUNTIF('LME Payment & Payoff'!$I$14:$I$2000,"Failed") | G29: =COUNTIF('LME Payment & Payoff'!$I$14:$I$2000,"Not Executed") | H29: =COUNTIF('LME Payment & Payoff'!$I$14:$I$2000,"Blocked")
A30: View Audit Trail | B30: Lending Management | C30: =COUNTA('LME Audit Trail'!$B$14:$B$2000) | D30: =COUNTIF('LME Audit Trail'!$H$14:$H$2000,"Yes") | E30: =COUNTIF('LME Audit Trail'!$I$14:$I$2000,"Passed") | F30: =COUNTIF('LME Audit Trail'!$I$14:$I$2000,"Failed") | G30: =COUNTIF('LME Audit Trail'!$I$14:$I$2000,"Not Executed") | H30: =COUNTIF('LME Audit Trail'!$I$14:$I$2000,"Blocked")
A31: Permissions | B31: Lending Management | C31: =COUNTA('LME Permissions'!$B$14:$B$2000) | D31: =COUNTIF('LME Permissions'!$H$14:$H$2000,"Yes") | E31: =COUNTIF('LME Permissions'!$I$14:$I$2000,"Passed") | F31: =COUNTIF('LME Permissions'!$I$14:$I$2000,"Failed") | G31: =COUNTIF('LME Permissions'!$I$14:$I$2000,"Not Executed") | H31: =COUNTIF('LME Permissions'!$I$14:$I$2000,"Blocked")
A32: UI Copy / Label Changes | B32: Lending Management | C32: =COUNTA('LME UI Copy Changes'!$B$14:$B$2000)
A33: Account | B33: Depository Management | C33: =COUNTA('DMS Account'!$B$14:$B$2000) | D33: =COUNTIF('DMS Account'!$H$14:$H$2000,"Yes") | E33: =COUNTIF('DMS Account'!$I$14:$I$2000,"Passed") | F33: =COUNTIF('DMS Account'!$I$14:$I$2000,"Failed") | G33: =COUNTIF('DMS Account'!$I$14:$I$2000,"Not Executed") | H33: =COUNTIF('DMS Account'!$I$14:$I$2000,"Blocked")
A34: Details & Daily Interest | B34: Depository Management | C34: =COUNTA('DMS Details & Interest'!$B$14:$B$2000) | D34: =COUNTIF('DMS Details & Interest'!$H$14:$H$2000,"Yes") | E34: =COUNTIF('DMS Details & Interest'!$I$14:$I$2000,"Passed") | F34: =COUNTIF('DMS Details & Interest'!$I$14:$I$2000,"Failed") | G34: =COUNTIF('DMS Details & Interest'!$I$14:$I$2000,"Not Executed") | H34: =COUNTIF('DMS Details & Interest'!$I$14:$I$2000,"Blocked")
A35: Configuration | B35: Depository Management | C35: =COUNTA('DMS Configuration'!$B$14:$B$2000) | D35: =COUNTIF('DMS Configuration'!$H$14:$H$2000,"Yes") | E35: =COUNTIF('DMS Configuration'!$I$14:$I$2000,"Passed") | F35: =COUNTIF('DMS Configuration'!$I$14:$I$2000,"Failed") | G35: =COUNTIF('DMS Configuration'!$I$14:$I$2000,"Not Executed") | H35: =COUNTIF('DMS Configuration'!$I$14:$I$2000,"Blocked")
A36: Account Category | B36: Depository Management | C36: =COUNTA('DMS Account Category'!$B$14:$B$2000) | D36: =COUNTIF('DMS Account Category'!$H$14:$H$2000,"Yes") | E36: =COUNTIF('DMS Account Category'!$I$14:$I$2000,"Passed") | F36: =COUNTIF('DMS Account Category'!$I$14:$I$2000,"Failed") | G36: =COUNTIF('DMS Account Category'!$I$14:$I$2000,"Not Executed") | H36: =COUNTIF('DMS Account Category'!$I$14:$I$2000,"Blocked")
A37: Interest Rate | B37: Depository Management | C37: =COUNTA('DMS Interest Rate'!$B$14:$B$2000) | D37: =COUNTIF('DMS Interest Rate'!$H$14:$H$2000,"Yes") | E37: =COUNTIF('DMS Interest Rate'!$I$14:$I$2000,"Passed") | F37: =COUNTIF('DMS Interest Rate'!$I$14:$I$2000,"Failed") | G37: =COUNTIF('DMS Interest Rate'!$I$14:$I$2000,"Not Executed") | H37: =COUNTIF('DMS Interest Rate'!$I$14:$I$2000,"Blocked")
A38: Fee Type | B38: Depository Management | C38: =COUNTA('DMS Fee Type'!$B$14:$B$2000) | D38: =COUNTIF('DMS Fee Type'!$H$14:$H$2000,"Yes") | E38: =COUNTIF('DMS Fee Type'!$I$14:$I$2000,"Passed") | F38: =COUNTIF('DMS Fee Type'!$I$14:$I$2000,"Failed") | G38: =COUNTIF('DMS Fee Type'!$I$14:$I$2000,"Not Executed") | H38: =COUNTIF('DMS Fee Type'!$I$14:$I$2000,"Blocked")
A39: Other Adjustment | B39: Depository Management | C39: =COUNTA('DMS Other Adj Type'!$B$14:$B$2000) | D39: =COUNTIF('DMS Other Adj Type'!$H$14:$H$2000,"Yes") | E39: =COUNTIF('DMS Other Adj Type'!$I$14:$I$2000,"Passed") | F39: =COUNTIF('DMS Other Adj Type'!$I$14:$I$2000,"Failed") | G39: =COUNTIF('DMS Other Adj Type'!$I$14:$I$2000,"Not Executed") | H39: =COUNTIF('DMS Other Adj Type'!$I$14:$I$2000,"Blocked")
A40: Adjustment | B40: Depository Management | C40: =COUNTA('DMS Adjustment'!$B$14:$B$2000) | D40: =COUNTIF('DMS Adjustment'!$H$14:$H$2000,"Yes") | E40: =COUNTIF('DMS Adjustment'!$I$14:$I$2000,"Passed") | F40: =COUNTIF('DMS Adjustment'!$I$14:$I$2000,"Failed") | G40: =COUNTIF('DMS Adjustment'!$I$14:$I$2000,"Not Executed") | H40: =COUNTIF('DMS Adjustment'!$I$14:$I$2000,"Blocked")
A41: Deposits | B41: Depository Management | C41: =COUNTA('DMS Deposits'!$B$14:$B$2000) | D41: =COUNTIF('DMS Deposits'!$H$14:$H$2000,"Yes") | E41: =COUNTIF('DMS Deposits'!$I$14:$I$2000,"Passed") | F41: =COUNTIF('DMS Deposits'!$I$14:$I$2000,"Failed") | G41: =COUNTIF('DMS Deposits'!$I$14:$I$2000,"Not Executed") | H41: =COUNTIF('DMS Deposits'!$I$14:$I$2000,"Blocked")
...

Sheet LME Loan Category
A1: Prepared By | B1: Subah Tasnim Shiary | D1: Total Test Cases | E1: =COUNTA('LME Loan Category'!$B$14:$B$1995)
A2: Executed By | B2: Subah Tasnim Shiary | D2: Passed | E2: =COUNTIF('LME Loan Category'!$I$14:$I$1995,"Passed")
A3: Updated On | B3: 46262 | D3: Failed | E3: =COUNTIF('LME Loan Category'!$I$14:$I$1995,"Failed")
A4: Time est | B4: Initial testing: | D4: Untested | E4: =COUNTIF('LME Loan Category'!$I$14:$I$1995,"Not Executed")
B5: Bugfix testing: | D5: To be tested | E5: =COUNTIF('LME Loan Category'!$I$14:$I$1995,"In Progress")+COUNTIF('LME Loan Category'!$I$14:$I$1995,"Blocked")
A6: common preconditions
A7: navigation
A8: Lending - Loan Category
A9: Common Preconditions | C9: 1. User is signed in to Sage Intacct. 2. The correct Lending Management or Depository Management entity is selected. 3. The module is enabled for the company. 4. The user has the permission required for the scenario. 5. Required master/configuration records are active and available.
A11: Navigation: Applications > Lending Management > Loan account category | Client baseline | 103 test cases | Updated 2026-08-31
A13: Test Case ID | B13: Test Scenario | C13: Preconditions | D13: Test Data | E13: Test Steps | F13: Expected Result | G13: Requirement/Jira Reference | H13: IS Automated | I13: Status | J13: Comments
A14: LISTER (39 test cases)
A15: LC-001 | B15: Verify the lister page title/heading identifies the Loan account category list | C15: Refer to Common Preconditions above. Navigate to Applications > Lending Management > Loan account category to open the lister page. | D15: N/A (observation only) | E15: 1. Sign in to Sage Intacct application 2. Navigate to Applications > Lending Management > Loan account category 3. Observe the page title/heading at the top of the lister page. | F15: - The lister page displays a clear title - 'Loan account categories'. | G15: IADSSL-101 | H15: No | I15: Not Executed
A16: LC-002 | B16: Verify the lister grid displays the documented columns | C16: Refer to Common Preconditions above. | D16: Expected default columns: Name, Document sequence | E16: 1. Sign in to Sage Intacct application 2. Navigate to Applications > Lending Management > Loan account category 3. Observe the columns displayed in the lister grid by default. | F16: - The lister grid displays the following columns by default: Name, Document sequence. - Status is available via Configure columns but is not shown by default. | G16: IADSSL-101 | H16: No | I16: Not Executed
A17: LC-003 | B17: Verify no column is sorted by default | C17: Refer to Common Preconditions above. | D17: N/A (observation only) | E17: 1. Sign in to Sage Intacct application 2. Navigate to Applications > Lending Management > Loan account category 3. Observe the column headers on page load for a default sort indicator. | F17: - The 'Name' column is sorted ascending by default, shown by an upward arrow indicator. - No other column shows a sort indicator. | G17: IADSSL-101 | H17: No | I17: Not Executed
A18: LC-004 | B18: Verify Name is a drillable field that routes to the View loan account category screen | C18: Refer to Common Preconditions above. | D18: Name: QA Loan Category A (existing record) | E18: 1. Sign in to Sage Intacct application 2. Navigate to Applications > Lending Management > Loan account category 3. Click a row's value in the Name column. | F18: - Clicking the Name value navigates to the View loan account category screen for that record. | G18: IADSSL-101 | H18: No | I18: Not Executed
A19: LC-005 | B19: Verify Document sequence is a drillable field that routes to the View loan account category screen | C19: Refer to Common Preconditions above. | D19: Document sequence: existing record with a populated Document sequence value | E19: 1. Sign in to Sage Intacct application 2. Navigate to Applications > Lending Management > Loan account category 3. Click a row's value in the Document sequence column. | F19: - Clicking the Document sequence value navigates to the View loan account category screen for that record. | G19: IADSSL-101 | H19: No | I19: Not Executed
A20: LC-006 | B20: Verify the '+Create' button is present and functional | C20: Refer to Common Preconditions above. | D20: N/A (observation/action only) | E20: 1. Sign in to Sage Intacct application 2. Navigate to Applications > Lending Management > Loan account category 3. Locate the '+Create' button at the top right of the lister page. 4. Click the '+Create' button. | F20: - The '+Create' button is located at the top right of the lister page. - Clicking the '+Create' button redirects to the 'Create loan account category' page. | G20: IADSSL-101 | H20: No | I20: Not Executed
A21: LC-007 | B21: Verify the lister view-selection dropdown functionality | C21: Refer to Common Preconditions above. | D21: N/A (observation only) | E21: 1. Sign in to Sage Intacct application 2. Navigate to Applications > Lending Management > Loan account category 3. Click the view-selection dropdown at the top left of the lister. 4. Select a view from the list. | F21: - Clicking the view dropdown opens a list with a 'Search for view' field, a 'System views' section (including 'All'), and a 'User views' section. - Selecting any view updates the lister to reflect that view. | G21: IADSSL-101 | H21: No | I21: Not Executed
A22: LC-008 | B22: Verify the Split view / List view toggle | C22: Refer to Common Preconditions above. | D22: N/A (observation only) | E22: 1. Sign in to Sage Intacct application 2. Navigate to Applications > Lending Management > Loan account category 3. Click the Split view icon. 4. Click the List view icon. | F22: - Split view splits the screen into the lister on the left and the record detail on the right. - List view shows only the lister in full screen. | G22: IADSSL-101 | H22: No | I22: Not Executed
A23: LC-009 | B23: Verify the 'Filters' button opens the Advanced filter modal | C23: Refer to Common Preconditions above. | D23: N/A (observation only) | E23: 1. Sign in to Sage Intacct application 2. Navigate to Applications > Lending Management > Loan account category 3. Click the 'Filters' button at the top right of the lister. | F23: - A modal titled 'Advanced filter' opens containing Field/Operator/Value/Apply-criteria columns, Apply and Cancel buttons, and per-row '+' (add) and '-' (remove) controls. - No filters are selected by default. | G23: IADSSL-101 | H23: No | I23: Not Executed
A24: LC-010 | B24: Verify the Advanced filter 'Apply' button applies and persists filter changes | C24: Refer to Common Preconditions above. | D24: Filter row: Field = Name, Operator = Contains, Value = QA | E24: 1. Sign in to Sage Intacct application 2. Navigate to Applications > Lending Management > Loan account category 3. Click 'Filters' to open the Advanced filter modal. 4. Set Field = Name, Operator = Contains, Value = QA, then click 'Apply'. 5. Reopen Advanced filters. | F24: - The modal closes and the list updates to reflect the filter changes. - Reopening Advanced filters shows the previously applied filters persisted. - Rows left without any Field/Operator/Value are ignored. | G24: IADSSL-101 | H24: No | I24: Not Executed
A25: LC-011 | B25: Verify column filters and Advanced filters stay in sync | C25: Refer to Common Preconditions above. | D25: Column filter: Name column, value = QA | E25: 1. Sign in to Sage Intacct application 2. Navigate to Applications > Lending Management > Loan account category 3. Enter 'QA' in the Name column's filter input and press Enter. 4. Open the Advanced filter modal and check whether the filter appears there. 5. Add/edit a filter in the Advanced filter modal and check it is reflected back in the column filter input. | F25: - Filters applied from a column filter input appear in the Advanced filter modal. - Filters added/edited in Manage view/Advanced filter are reflected back in the column filter inputs. | G25: IADSSL-101 | H25: No | I25: Not Executed
A26: LC-012 | B26: Verify column sorting from the column header | C26: Refer to Common Preconditions above. | D26: Column: Name | E26: 1. Sign in to Sage Intacct application 2. Navigate to Applications > Lending Management > Loan account category 3. Click the Name column header once. 4. Click the Name column header a second time. | F26: - The first click sorts the column ascending with an upward arrow indicator. - The second click sorts descending with a downward arrow indicator. | G26: IADSSL-101 | H26: No | I26: Not Executed
... A53: LC-039 | B53: Verify overall lister UI consistency (spacing, alignment, controls) matches the design standard | C53: Refer to Common Preconditions above. | D53: N/A (visual inspection only) | E53: 1. Sign in to Sage Intacct application 2. Navigate to Applications > Lending Management > Loan account category 3. Visually inspect the lister page's headers, buttons, filters, and grid layout, spacing, and alignment. | F53: - The page header, buttons, column filters, and data grid use the same spacing, alignment, and control styling as every other module lister in the application, with no visibly misaligned, overlapping, or inconsistently styled element. | G53: IADSSL-101 | H53: No | I53: Not Executed
A54: CREATE (37 test cases)
A55: LC-040 | B55: Verify that create page title is 'Create loan account category' | C55: Refer to Common Preconditions above. | D55: Name: QA Loan Category Description: Client QA loan category Status: Active | E55: 1. Sign in to Sage Intacct application 2. Navigate to Applications > Lending Management > Loan account category 3. Click '+Create'. | F55: - The page title/heading reads exactly "Create loan account category". | G55: IADSSL-101 | H55: No | I55: Not Executed | J55: [UPDATED - title quoted exactly per client request]
A56: LC-041 | B56: verify that create page contains following sections Loan category information | C56: Refer to Common Preconditions above. | D56: N/A (observation only) | E56: 1. Sign in to Sage Intacct application 2. Navigate to Applications > Lending Management > Loan account category 3. Click '+Create'. | F56: - The Create page displays a 'Loan account category information' section (not 'Loan category information'). | G56: IADSSL-101 | H56: No | I56: Not Executed
A57: LC-042 | B57: Verify that Name is a mandatory field with red * mark | C57: Refer to Common Preconditions above. | D57: Name: (leave blank) Description: Client QA loan category Status: Active | E57: 1. Sign in to Sage Intacct application 2. Navigate to Applications > Lending Management > Loan account category 3. Click '+Create'. | F57: - The Name field label is marked with a red asterisk (*), indicating it is a mandatory field. | G57: IADSSL-101 | H57: No | I57: Not Executed
A58: LC-043 | B58: Verify record can be created successfully with a valid name | C58: Refer to Common Preconditions above. | D58: Name: QA Loan Category Description: Client QA loan category Status: Active | E58: 1. Sign in to Sage Intacct application 2. Navigate to Applications > Lending Management > Loan account category 3. Click '+Create'. 4. Enter 'QA Loan Category' in the Name field, 'Client QA loan category' in the Description field, and set Status to Active. 5. Click 'Save'. | F58: - The record saves successfully. - The View page displays 'QA Loan Category' in the Name field. | G58: IADSSL-101 | H58: No | I58: Not Executed
A59: LC-044 | B59: Verify max length of name is 200 characters | C59: Refer to Common Preconditions above. | D59: Name (200 chars, at limit): QA Name QA Name QA Name QA Name QA Name QA Name QA Name QA Name QA Name QA Name QA Name QA Name QA Name QA Name QA Name QA Name QA Name QA Name QA Name QA Name QA Name QA Name QA Name QA Name QA Name Description: Client QA loan category Status: Active | E59: 1. Sign in to Sage Intacct application 2. Navigate to Applications > Lending Management > Loan account category 3. Click '+Create'. 4. Enter the 200-character Name value (at the character limit) in the Name field, along with valid Description and Status. 5. Click 'Save'. | F59: - The record saves successfully with the full 200-character Name value accepted and displayed on the View page. - This confirms the maximum allowed length for the Name field is 200 characters. | G59: IADSSL-101 | H59: No | I59: Not Executed
A60: LC-045 | B60: Verify that an error is returned when the name field value is more than 200 character | C60: Refer to Common Preconditions above. | D60: Name (201 chars, over limit): QA Name QA Name QA Name QA Name QA Name QA Name QA Name QA Name QA Name QA Name QA Name QA Name QA Name QA Name QA Name QA Name QA Name QA Name QA Name QA Name QA Name QA Name QA Name QA Name QA Name Q Description: Client QA loan category Status: Active | E60: 1. Sign in to Sage Intacct application 2. Navigate to Applications > Lending Management > Loan account category 3. Click '+Create'. 4. Enter the 201-character Name value (one over the limit) in the Name field, along with valid Description and Status. 5. Click 'Save'. | F60: - A validation error appears stating the Name field cannot exceed 200 characters. - The record is not saved. | G60: IADSSL-101 | H60: No | I60: Not Executed
A61: LC-046 | B61: Verify that proper error is returned when the name field value is null/empty string | C61: Refer to Common Preconditions above. | D61: Name: (leave blank) Description: Client QA loan category Status: Active | E61: 1. Sign in to Sage Intacct application 2. Navigate to Applications > Lending Management > Loan account category 3. Click '+Create'. 4. Leave the Name field blank, enter valid Description and Status values. 5. Click 'Save'. | F61: - A validation error appears stating the Name field is required. - The record is not saved. | G61: IADSSL-101 | H61: No | I61: Not Executed
A62: LC-047 | B62: Verify that an error is returned when the name field value is white space only | C62: Refer to Common Preconditions above. | D62: Name: ' ' (three spaces, whitespace only) Description: Client QA loan category Status: Active | E62: 1. Sign in to Sage Intacct application 2. Navigate to Applications > Lending Management > Loan account category 3. Click '+Create'. 4. Enter three spaces (whitespace only) in the Name field, and valid Description and Status values. 5. Click 'Save'. | F62: - A validation error appears stating the Name field is required, since whitespace-only input is treated as blank. - The record is not saved. | G62: IADSSL-101 | H62: No | I62: Not Executed
A63: LC-048 | B63: Verify that an error is returned when the name field value is in invalid format | C63: Refer to Common Preconditions above. | D63: Name: <<>>###!!! (invalid/disallowed characters) Description: Client QA loan category Status: Active | E63: 1. Sign in to Sage Intacct application 2. Navigate to Applications > Lending Management > Loan account category 3. Click '+Create'. 4. Enter '<<>>###!!!' in the Name field, and valid Description and Status values. 5. Click 'Save'. | F63: - A validation error appears stating the Name field value is in an invalid format. - The record is not saved. | G63: IADSSL-101 | H63: No | I63: Not Executed
A64: LC-049 | B64: Reject creating a record with a duplicate Name | C64: Refer to Common Preconditions above. A record already exists with Name = 'QA Loan Category A'. | D64: Name: QA Loan Category A Existing record with the same Name: QA Loan Category A | E64: 1. Sign in to Sage Intacct application 2. Navigate to Applications > Lending Management > Loan account category 3. Confirm a record already exists with Name = 'QA Loan Category A'. 4. Click '+Create' and enter Name = 'QA Loan Category A' (the same value), with valid Description and Status. 5. Click 'Save'. | F64: - [DEFECT] A validation error appears reading exactly "Another loan-management/loan-category with name <Name> already exists. Use a unique value instead." This leaks the internal API object path ('loan-management/loan-category') to the end user instead of a friendly label like 'loan account category'. - Submission is blocked and the duplicate record is not created. | G64: IADSSL-101 | H64: No | I64: Not Executed
A65: LC-050 | B65: Verify Description is not a mandatory field | C65: Refer to Common Preconditions above. | D65: Name: QA Loan Category Description: (leave blank) Status: Active | E65: 1. Sign in to Sage Intacct application 2. Navigate to Applications > Lending Management > Loan account category 3. Click '+Create'. 4. Enter 'QA Loan Category' in the Name field, leave the Description field blank, and set Status to Active. 5. Click 'Save'. | F65: - The record saves successfully with no error raised for the blank Description field, confirming Description is not mandatory. | G65: IADSSL-101 | H65: No | I65: Not Executed
A66: LC-051 | B66: Verify that a valid description within 500 characters is accepted | C66: Refer to Common Preconditions above. | D66: Name: QA Loan Category Description (500 chars, at limit): QA Description QA Description QA Description QA Description QA Description QA Description QA Description QA Description QA Description QA Description QA Description QA Description QA Description QA Description QA Description QA Description QA Description QA Description QA Description QA Description QA Description QA Description QA Description QA Description QA Description QA Descrip Status: Active | E66: 1. Sign in to Sage Intacct application 2. Navigate to Applications > Lending Management > Loan account category 3. Click '+Create'. 4. Enter 'QA Loan Category' in the Name field and a 500-character Description value, and set Status to Active. 5. Click 'Save'. | F66: - The record saves successfully with the full 500-character Description value accepted and displayed on the View page. | G66: IADSSL-101 | H66: No | I66: Not Executed
A67: LC-052 | B67: Verify that an empty description is accepted | C67: Refer to Common Preconditions above. | D67: Name: QA Loan Category Description: (leave blank) Status: Active | E67: 1. Sign in to Sage Intacct application 2. Navigate to Applications > Lending Management > Loan account category 3. Click '+Create'. 4. Enter 'QA Loan Category' in the Name field, leave the Description field blank, and set Status to Active. 5. Click 'Save'. | F67: - The record saves successfully with the Description field accepted as empty. | G67: IADSSL-101 | H67: No | I67: Not Executed
A68: LC-053 | B68: Verify that a description exceeding 500 characters is not allowed | C68: Refer to Common Preconditions above. | D68: Name: QA Loan Category Description (501 chars, over limit): QA Description QA Description QA Description QA Description QA Description QA Description QA Description QA Description QA Description QA Description QA Description QA Description QA Description QA Description QA Description QA Description QA Description QA Description QA Description QA Description QA Description QA Description QA Description QA Description QA Description QA Descrip1 Status: Active | E68: 1. Sign in to Sage Intacct application 2. Navigate to Applications > Lending Management > Loan account category 3. Click '+Create'. 4. Enter 'QA Loan Category' in the Name field and a 501-character Description value (one over the 500-character limit), and set Status to Active. 5. Click 'Save'. | F68: - A validation error appears stating the Description field cannot exceed the configured character limit. - The record is not saved. | G68: IADSSL-101 | H68: No | I68: Not Executed
...

Sheet LME Loan Account
A1: Prepared By | B1: Subah Tasnim Shiary | D1: Total Test Cases | E1: =COUNTA('LME Loan Account'!$B$14:$B$2000)
A2: Executed By | B2: Subah Tasnim Shiary | D2: Passed | E2: =COUNTIF('LME Loan Account'!$I$14:$I$2000,"Passed")
A3: Updated On | B3: 46262 | D3: Failed | E3: =COUNTIF('LME Loan Account'!$I$14:$I$2000,"Failed")
A4: Time est | B4: Initial testing: | D4: Untested | E4: =COUNTIF('LME Loan Account'!$I$14:$I$2000,"Not Executed")
B5: Bugfix testing: | D5: To be tested | E5: =COUNTIF('LME Loan Account'!$I$14:$I$2000,"In Progress")+COUNTIF('LME Loan Account'!$I$14:$I$2000,"Blocked")
A6: common preconditions
A7: navigation
A8: Lending - Loan Account
A9: Common Preconditions | C9: 1. User is signed in to Sage Intacct. 2. The correct Lending Management or Depository Management entity is selected. 3. The module is enabled for the company. 4. The user has the permission required for the scenario. 5. Required master/configuration records are active and available.
A11: Navigation: Applications > Lending Management > Loan account | Client baseline | 220 test cases | Updated 2026-08-31
A13: Test Case ID | B13: Test Scenario | C13: Preconditions | D13: Test Data | E13: Test Steps | F13: Expected Result | G13: Requirement/Jira Reference | H13: IS Automated | I13: Status | J13: Comments
A14: LISTER (40 test cases)
A15: LA-001 | B15: Page title is 'Loans' | C15: Refer to Common Preconditions above. | D15: Account category: QA Loan Category Account number: LA-QA-001 User role: Full Access | E15: 1. Sign in to Sage Intacct application 2. Navigate to Applications > Lending Management > Loan account 3. Open the Loan account lister page 4. Observe the page header at the top of the page. | F15: - The page header (H1) displays "Loans". | G15: IADSSL-101 | H15: No | I15: Not Executed | J15: Source section: A. List page (IDs: TC-LA-131–145)
A16: LA-002 | B16: Verify the lister grid displays the documented columns | C16: Refer to Common Preconditions above. | D16: Expected columns (default lister grid, verified live 2026-08-31): Account number, Account name, Loan type name, Loan type, First loan invoice date, First payment date, First statement date, Record number, Amount, Loan origination date | E16: 1. Sign in to Sage Intacct application 2. Navigate to Applications > Lending Management > Loan account 3. Open the Loan account lister page 4. Observe the columns displayed in the lister grid. | F16: - The lister grid displays the following columns by default: Account number, Account name, Loan type name, Loan type, First loan invoice date, First payment date, First statement date, Record number, Amount, Loan origination date. - Account category, Customer, Vendor, State, and Status are real fields on the loan record but are not default lister columns - they are covered separately by the View-band field-display test cases. | G16: IADSSL-101 | H16: No | I16: Not Executed | J16: [UPDATED]
A17: LA-003 | B17: Verify no column is sorted by default | C17: Refer to Common Preconditions above. | D17: N/A | E17: 1. Sign in to Sage Intacct application 2. Navigate to Applications > Lending Management > Loan account 3. Open the Loan account lister page and inspect the column headers. | F17: - No column header shows a sort arrow/indicator by default. - The grid loads in its natural, unsorted order. | G17: IADSSL-101 | H17: No | I17: Not Executed
A18: LA-004 | B18: Verify Account number is a drillable field that routes to the View loan account screen | C18: Refer to Common Preconditions above. | D18: A record with a valid Account number value exists. | E18: 1. Sign in to Sage Intacct application 2. Navigate to Applications > Lending Management > Loan account 3. Open the Loan account lister page 4. Click the Account number value on any row. | F18: - Clicking the Account number value navigates to the View loan account screen for that record. | G18: IADSSL-101 | H18: No | I18: Not Executed
A19: LA-005 | B19: Verify Account name is a drillable field that routes to the View loan account screen | C19: Refer to Common Preconditions above. | D19: A record with a valid Account name value exists. | E19: 1. Sign in to Sage Intacct application 2. Navigate to Applications > Lending Management > Loan account 3. Open the Loan account lister page 4. Click the Account name value on any row. | F19: - Clicking the Account name value navigates to the View loan account screen for that record. | G19: IADSSL-101 | H19: No | I19: Not Executed
A20: LA-006 | B20: Verify the '+Create' button is present and functional | C20: Refer to Common Preconditions above. | D20: N/A | E20: 1. Sign in to Sage Intacct application 2. Navigate to Applications > Lending Management > Loan account 3. Open the Loan account lister page 4. Locate the '+Create' button at the top right of the lister page and click it. | F20: - The '+Create' button is located at the top right of the lister page. - Clicking '+Create' redirects to the 'Create loan account' page. | G20: IADSSL-101 | H20: No | I20: Not Executed
A21: LA-007 | B21: Verify the lister view-selection dropdown functionality | C21: Refer to Common Preconditions above. | D21: N/A | E21: 1. Sign in to Sage Intacct application 2. Navigate to Applications > Lending Management > Loan account 3. Open the Loan account lister page 4. Click the view-selection dropdown at the top left and inspect its contents, then select a view. | F21: - Clicking the view dropdown opens a list with a 'Search for view' field, a 'System views' section (including 'All'), and a 'User views' section. - Selecting any view updates the lister to reflect that view. | G21: IADSSL-101 | H21: No | I21: Not Executed
A22: LA-008 | B22: Verify the Split view / List view toggle | C22: Refer to Common Preconditions above. | D22: N/A | E22: 1. Sign in to Sage Intacct application 2. Navigate to Applications > Lending Management > Loan account 3. Open the Loan account lister page 4. Click the Split view icon 5. Click the List view icon. | F22: - Split view splits the screen into the lister on the left and the record detail on the right. - List view shows only the lister in full screen. | G22: IADSSL-101 | H22: No | I22: Not Executed
A23: LA-009 | B23: Verify the 'Filters' button opens the Advanced filter modal | C23: Refer to Common Preconditions above. | D23: N/A | E23: 1. Sign in to Sage Intacct application 2. Navigate to Applications > Lending Management > Loan account 3. Open the Loan account lister page 4. Click the 'Filters' button at the top right of the lister. | F23: - A modal titled 'Advanced filter' opens containing Field/Operator/Value/Apply-criteria columns, Apply and Cancel buttons, and per-row '+' (add) and '-' (remove) controls. - No filters are selected by default. | G23: IADSSL-101 | H23: No | I23: Not Executed
A24: LA-010 | B24: Verify the Advanced filter 'Apply' button applies and persists filter changes | C24: Refer to Common Preconditions above. | D24: Filter row: Field = Account category, Operator = Equals, Value = QA Loan Category | E24: 1. Sign in to Sage Intacct application 2. Navigate to Applications > Lending Management > Loan account 3. Open the Loan account lister page and click 'Filters' to open the Advanced filter modal 4. Add/edit/delete one or more filter rows (e.g. Field: Account category, Operator: Equals, Value: QA Loan Category), leaving any incomplete rows blank 5. Click 'Apply' 6. Reopen the Advanced filter modal. | F24: - Clicking 'Apply' closes the modal and the list updates to reflect the filter changes. - Reopening Advanced filters shows the previously applied filters persisted. - Rows left without any Field/Operator/Value are ignored. | G24: IADSSL-101 | H24: No | I24: Not Executed
A25: LA-011 | B25: Verify column filters and Advanced filters stay in sync | C25: Refer to Common Preconditions above. | D25: Column filter: Account category contains 'QA' | E25: 1. Sign in to Sage Intacct application 2. Navigate to Applications > Lending Management > Loan account 3. Open the Loan account lister page 4. Apply a filter via a column header's filter input (e.g. Account category contains 'QA'), then open the Advanced filter modal and check that it appears there 5. In the Advanced filter modal, add or edit a filter and click Apply, then check the corresponding column filter input. | F25: - Filters applied from a column filter input appear in the Advanced filter modal. - Filters added or edited in Manage view/Advanced filter are reflected back in the column filter inputs. | G25: IADSSL-101 | H25: No | I25: Not Executed
A26: LA-012 | B26: Verify column sorting from the column header | C26: Refer to Common Preconditions above. | D26: Column: Account number | E26: 1. Sign in to Sage Intacct application 2. Navigate to Applications > Lending Management > Loan account 3. Open the Loan account lister page 4. Click the Account number column header once 5. Click the Account number column header again. | F26: - The first click sorts the column ascending with an upward arrow indicator. - The second click sorts descending with a downward arrow indicator. | G26: IADSSL-101 | H26: No | I26: Not Executed
A27: LA-013 | B27: Verify column sorting from 'Configure column' / 'Column setting' options, including multi-column sort | C27: Refer to Common Preconditions above. | D27: Sort row 1: Account category, Ascending Sort row 2: Account number, Descending | E27: 1. Sign in to Sage Intacct application 2. Navigate to Applications > Lending Management > Loan account 3. Open the Loan account lister page and open the column header's Column setting (cog wheel) menu, or Settings > Sort 4. Choose Account category and Ascending order, click Apply 5. Add a second sort row for Account number set to Descending order, click Apply. | F27: - The grid sorts ascending/descending per the chosen order with the matching arrow indicator. - When multiple sort rows are configured, the dataset sorts by the first row's order first, then the second row's order for ties, continuing for any additional rows added. | G27: IADSSL-101 | H27: No | I27: Not Executed
A28: LA-014 | B28: Verify the 'Column setting' (cog wheel) menu functionality | C28: Refer to Common Preconditions above. | D28: N/A | E28: 1. Sign in to Sage Intacct application 2. Navigate to Applications > Lending Management > Loan account 3. Open the Loan account lister page 4. Click the Column setting/cog wheel icon on a column header. | F28: - A menu appears with Sort ascending, Sort descending, Freeze, Unfreeze all, and Text Wrapping (Clip / Wrap) options. | G28: IADSSL-101 | H28: No | I28: Not Executed
... A53: LA-039 | B53: Verify overall lister UI consistency (spacing, alignment, controls) matches the design standard | C53: Refer to Common Preconditions above. | D53: N/A | E53: 1. Sign in to Sage Intacct application 2. Navigate to Applications > Lending Management > Loan account 3. Open the Loan account lister page and visually inspect its layout, spacing, headers, buttons, filters, and grid. | F53: - The page header, buttons, column filters, and data grid use the same spacing, alignment, and control styling as every other module lister in the application, with no visibly misaligned, overlapping, or inconsistently styled element. | G53: IADSSL-101 | H53: No | I53: Not Executed
A54: LA-040 | B54: [KNOWN DEFECT] 'Loan account' tile on module landing page does not respond to clicks | C54: Refer to Common Preconditions above. | D54: N/A - module landing page navigation only | E54: 1. Sign in to Sage Intacct application 2. Navigate to Applications > Lending Management (module landing page, not the top-nav dropdown) 3. Click the 'Loan account' tile 4. Observe whether the page navigates. | F54: - [DEFECT] Clicking the 'Loan account' tile on the Lending Management module landing page does nothing - no navigation occurs and no network request fires. - The sibling 'Loan account categories' and 'Loan interest rates' tiles on the same page navigate correctly when clicked. - The Loan account lister page is still reachable via the top navigation bar's Lending Management dropdown > Transactions > Loan account link, which works correctly. | G54: IADSSL-101 | H54: TBD | I54: Not Executed | J54: [ADDED - verified live 2026-08-31]
A55: CREATE (78 test cases)
A56: LA-041 | B56: Page title is 'Create loan' | C56: Refer to Common Preconditions above. | D56: Account category: QA Loan Category Account number: LA-QA-001 | E56: 1. Sign in to Sage Intacct application 2. Navigate to Applications > Lending Management > Loan account 3. Click the '+Create' button 4. Observe the page header at the top of the page. | F56: - The page header (H1) displays "Create loan". | G56: IADSSL-101 | H56: No | I56: Not Executed | J56: Source section: B. Create page (IDs: TC-LA-001–058)
A57: LA-042 | B57: Loan information section present | C57: Refer to Common Preconditions above. | D57: Account category: QA Loan Category Account number: LA-QA-001 | E57: 1. Sign in to Sage Intacct application 2. Navigate to Applications > Lending Management > Loan account 3. Click the '+Create' button to open the Create loan account page. | F57: - The 'Loan information' section heading is visible on the Create loan account page. | G57: IADSSL-101 | H57: No | I57: Not Executed | J57: Source section: B. Create page (IDs: TC-LA-001–058)
A58: LA-043 | B58: Loan information fields present | C58: Refer to Common Preconditions above. | D58: Account category: QA Loan Category Account number: LA-QA-001 Account name: Client QA Loan 001 Customer: 1--Power Aerospace Materials Loan type: QA Non-Revolving Interest rate: 5.0000% Origination amount: 10000.00 Origination date: 2026-08-01 | E58: 1. Sign in to Sage Intacct application 2. Navigate to Applications > Lending Management > Loan account 3. Click the '+Create' button to open the Create loan account page 4. Inspect the 'Loan information' section. | F58: - The Account category, Account number, Account name, Customer, Vendor, Attachment, Description, Email statements, and Amount fields are all present on the Create loan account page. | G58: IADSSL-101 | H58: No | I58: Not Executed | J58: Source section: B. Create page (IDs: TC-LA-001–058)
A59: LA-044 | B59: Account category mandatory | C59: Refer to Common Preconditions above. | D59: Account category: (leave blank) Account number: LA-QA-001 Account name: Client QA Loan 001 Customer: 1--Power Aerospace Materials | E59: 1. Sign in to Sage Intacct application 2. Navigate to Applications > Lending Management > Loan account 3. Click the '+Create' button to open the Create loan account page 4. Inspect the Account category field label. | F59: - The Account category field label displays a red asterisk indicating it is a mandatory field. | G59: IADSSL-101 | H59: No | I59: Not Executed | J59: Source section: B. Create page (IDs: TC-LA-001–058)
A60: LA-045 | B60: Empty Account category error | C60: Refer to Common Preconditions above. | D60: Account category: (leave blank) Account number: LA-QA-001 Account name: Client QA Loan 001 Customer: 1--Power Aerospace Materials | E60: 1. Sign in to Sage Intacct application 2. Navigate to Applications > Lending Management > Loan account 3. Click the '+Create' button to open the Create loan account page 4. Leave the Account category field blank, complete the other required fields (Account number: LA-QA-001, Account name: Client QA Loan 001, Customer: 1--Power Aerospace Materials), and click 'Save'. | F60: - A validation error banner appears reading "Correct the fields below and try again." - A per-field line reads "Account category: Field is required." - The record is not saved. | G60: IADSSL-101 | H60: No | I60: Not Executed | J60: Source section: B. Create page (IDs: TC-LA-001–058)
A61: LA-046 | B61: Account category dropdown active-only | C61: Refer to Common Preconditions above. | D61: Account category: QA Loan Category Account number: LA-QA-001 Account name: Client QA Loan 001 Customer: 1--Power Aerospace Materials Loan type: QA Non-Revolving Interest rate: 5.0000% Origination amount: 10000.00 Origination date: 2026-08-01 | E61: 1. Sign in to Sage Intacct application 2. Navigate to Applications > Lending Management > Loan account 3. Click '+Create'. 4. Click the Account category dropdown. | F61: - Only active account categories (e.g. QA Loan Category) are listed. - Inactive categories do not appear. | G61: IADSSL-101 | H61: No | I61: Not Executed | J61: Source section: B. Create page (IDs: TC-LA-001–058)
A62: LA-047 | B62: Account number mandatory | C62: Refer to Common Preconditions above. | D62: Account category: QA Loan Category Account number: (leave blank) Account name: Client QA Loan 001 Customer: 1--Power Aerospace Materials | E62: 1. Sign in to Sage Intacct application 2. Navigate to Applications > Lending Management > Loan account 3. Click the '+Create' button to open the Create loan account page 4. Inspect the Account number field label. | F62: - The Account number field label displays a red asterisk indicating it is a mandatory field. | G62: IADSSL-101 | H62: No | I62: Not Executed | J62: Source section: B. Create page (IDs: TC-LA-001–058)
A63: LA-048 | B63: Empty Account number (no-sequence category) | C63: Refer to Common Preconditions above. | D63: Account category: QA Loan Category (no auto-sequence configured) Account number: (leave blank) Account name: Client QA Loan 001 Customer: 1--Power Aerospace Materials | E63: 1. Sign in to Sage Intacct application 2. Navigate to Applications > Lending Management > Loan account 3. Click the '+Create' button to open the Create loan account page 4. Select Account category 'QA Loan Category' (a category with no auto-numbering sequence configured), leave Account number blank, complete the other required fields, and click 'Save'. | F63: - A friendly validation error appears stating that Account number is required. - No internal object path or technical identifier is exposed in the message. - The record is not saved. | G63: IADSSL-101 | H63: No | I63: Not Executed | J63: Source section: B. Create page (IDs: TC-LA-001–058)
A64: LA-049 | B64: Account number accepts string value | C64: Refer to Common Preconditions above. | D64: Account category: QA Loan Category Account number: LA-QA-001 Account name: Client QA Loan 001 Customer: 1--Power Aerospace Materials Loan type: QA Non-Revolving Interest rate: 5.0000% Origination amount: 10000.00 Origination date: 2026-08-01 | E64: 1. Sign in to Sage Intacct application 2. Navigate to Applications > Lending Management > Loan account 3. Click '+Create'. 4. Enter 'LA-QA-001' (a hyphenated alphanumeric string) in the Account number field, and enter valid values in all other required fields. 5. Click 'Save'. | F64: - The record saves successfully with the hyphenated Account number string saved as entered. | G64: IADSSL-101 | H64: No | I64: Not Executed | J64: Source section: B. Create page (IDs: TC-LA-001–058)
A65: LA-050 | B65: Whitespace Account number rejected | C65: Refer to Common Preconditions above. | D65: Account category: QA Loan Category Account number: " " (whitespace only) Account name: Client QA Loan 001 Customer: 1--Power Aerospace Materials Loan type: QA Non-Revolving Interest rate: 5.0000% Origination amount: 10000.00 Origination date: 2026-08-01 | E65: 1. Sign in to Sage Intacct application 2. Navigate to Applications > Lending Management > Loan account 3. Click '+Create'. 4. Enter a whitespace-only value (e.g. spaces) in the Account number field, and enter valid values in all other required fields. 5. Click 'Save'. | F65: - A friendly validation error appears stating the Account number is required/invalid. - The record is not saved. | G65: IADSSL-101 | H65: No | I65: Not Executed | J65: Source section: B. Create page (IDs: TC-LA-001–058)
A66: LA-051 | B66: Reject a supplied account ID when the category has a document sequence | C66: Refer to Common Preconditions above. | D66: Account category: QA-LC-SEQUENCED (has a document sequence) Account number (ID supplied): MANUAL-001 | E66: 1. Sign in to Sage Intacct application 2. Navigate to Applications > Lending Management > Loan account 3. Select the QA-LC-SEQUENCED account category (configured with a document sequence). 4. Manually enter 'MANUAL-001' in the Account number field instead of leaving it for auto-generation, and complete the remaining required fields. 5. Click 'Save'. | F66: - Creation is blocked with a validation error stating the Account number cannot be manually supplied for a category with a document sequence, since sequenced categories must generate the ID server-side. | G66: IADSSL-101 | H66: No | I66: Not Executed
...

Sheet LME Configuration
A1: Prepared By | B1: Subah Tasnim Shiary | D1: Total Test Cases | E1: =COUNTA('LME Configuration'!$B$14:$B$2000)
A2: Executed By | B2: Subah Tasnim Shiary | D2: Passed | E2: =COUNTIF('LME Configuration'!$I$14:$I$2000,"Passed")
A3: Updated On | B3: 46262 | D3: Failed | E3: =COUNTIF('LME Configuration'!$I$14:$I$2000,"Failed")
A4: Time est | B4: Initial testing: | D4: Untested | E4: =COUNTIF('LME Configuration'!$I$14:$I$2000,"Not Executed")
B5: Bugfix testing: | D5: To be tested | E5: =COUNTIF('LME Configuration'!$I$14:$I$2000,"In Progress")+COUNTIF('LME Configuration'!$I$14:$I$2000,"Blocked")
A6: common preconditions
A7: navigation
A8: Lending - Configuration
A9: Common Preconditions | C9: 1. User is signed in to Sage Intacct. 2. The correct Lending Management or Depository Management entity is selected. 3. The module is enabled for the company. 4. The user has the permission required for the scenario. 5. Required master/configuration records are active and available.
A11: Navigation: Applications > Lending Management > Configuration | Client baseline | 32 test cases | Updated 2026-08-31
A13: Test Case ID | B13: Test Scenario | C13: Preconditions | D13: Test Data | E13: Test Steps | F13: Expected Result | G13: Requirement/Jira Reference | H13: IS Automated | I13: Status | J13: Comments
A14: Initial setup (Create configuration) (10 test cases)
A15: CFG-001 | B15: Confirm the page title/heading on the initial Lending Management Configuration setup page | C15: Refer to Common Preconditions above. The Lending Management module has not yet been configured (no configuration record exists). | D15: Navigation: Applications > Lending Management > Configuration (no configuration saved yet) | E15: 1. Sign in to Sage Intacct application. 2. Navigate to Applications > Lending Management > Configuration before any configuration has been saved. 3. Observe the page title/heading. | F15: - The page title/heading clearly identifies the page as the Lending Management configuration setup page, consistent with the module/feature naming used elsewhere in Lending Management (e.g. 'Lending Management Configuration'). - The page title/heading is not blank, generic, or mismatched. | G15: IADSSL-101 | H15: No | I15: Not Executed
A16: CFG-002 | B16: Confirm the Lending Management configuration setup is required when the module is first subscribed | C16: Refer to Common Preconditions above. | D16: Company: newly subscribed to Lending Management Configuration record: none exists yet | E16: 1. Sign in to Sage Intacct application. 2. Navigate to Applications > Lending Management > Configuration for a company where the module was just subscribed. 3. Observe the page presented before any configuration has been saved. | F16: - The Lending Management configuration page requires the user to complete initial setup (Journals, GL accounts, Banking, Enable functionality, and Interest/invoice/statement generation settings) before Lending Management features can be used. | G16: IADSSL-101 | H16: No | I16: Not Executed | J16: Setup is a one-time step performed when a new company is created and Lending Management is subscribed.
A17: CFG-003 | B17: Confirm the Journals section accepts only active journal values on initial Create | C17: Refer to Common Preconditions above. | D17: Write-offs journal: LOAN--Loan Journal Adjustments journal: LOAN--Loan Journal Loan fees journal: LOAN--Loan Journal Inactive journal candidate: INACTIVE-JRNL | E17: 1. Sign in to Sage Intacct application. 2. Navigate to Applications > Lending Management > Configuration. 3. Open the initial Create configuration form. 4. Click the Write-offs journal dropdown and review the listed options; repeat for the Adjustments journal and Loan fees journal dropdowns. | F17: - The Write-offs journal dropdown lists only active journals. - The Adjustments journal dropdown lists only active journals. - The Loan fees journal dropdown lists only active journals. - No inactive journal (e.g. INACTIVE-JRNL) appears in any of the three dropdowns. | G17: IADSSL-101 | H17: No | I17: Not Executed
