Workbook

Sheet Summary
A1: Client Test Cases — Lending and Depository Management
A2: Detailed functional test cases with explicit preconditions, data, steps, and expected results. Statuses are reset for client execution.
A4: Module | B4: Area | C4: Test Cases | D4: Automated | E4: Passed | F4: Failed | G4: Not Executed | H4: Blocked
A5: Loan Account | B5: Lending Management | C5: =COUNTA('LME Loan Account'!$A$7:$A$143)-4 | D5: =COUNTIF('LME Loan Account'!$H$7:$H$143,"Yes") | E5: =COUNTIF('LME Loan Account'!$I$7:$I$143,"Passed") | F5: =COUNTIF('LME Loan Account'!$I$7:$I$143,"Failed") | G5: =COUNTIF('LME Loan Account'!$I$7:$I$143,"Not Executed") | H5: =COUNTIF('LME Loan Account'!$I$7:$I$143,"Blocked")
A6: Loan Type | B6: Lending Management | C6: =COUNTA('LME Loan Type'!$A$7:$A$77)-4 | D6: =COUNTIF('LME Loan Type'!$H$7:$H$77,"Yes") | E6: =COUNTIF('LME Loan Type'!$I$7:$I$77,"Passed") | F6: =COUNTIF('LME Loan Type'!$I$7:$I$77,"Failed") | G6: =COUNTIF('LME Loan Type'!$I$7:$I$77,"Not Executed") | H6: =COUNTIF('LME Loan Type'!$I$7:$I$77,"Blocked")
A7: Loan Type Automation Method | B7: Lending Management | C7: =COUNTA('LME Automation Method'!$A$7:$A$17)-4 | D7: =COUNTIF('LME Automation Method'!$H$7:$H$17,"Yes") | E7: =COUNTIF('LME Automation Method'!$I$7:$I$17,"Passed") | F7: =COUNTIF('LME Automation Method'!$I$7:$I$17,"Failed") | G7: =COUNTIF('LME Automation Method'!$I$7:$I$17,"Not Executed") | H7: =COUNTIF('LME Automation Method'!$I$7:$I$17,"Blocked")
A8: Loan Type Standard Automation | B8: Lending Management | C8: =COUNTA('LME Loan Type - Standard'!$A$7:$A$45)-4 | D8: =COUNTIF('LME Loan Type - Standard'!$H$7:$H$45,"Yes") | E8: =COUNTIF('LME Loan Type - Standard'!$I$7:$I$45,"Passed") | F8: =COUNTIF('LME Loan Type - Standard'!$I$7:$I$45,"Failed") | G8: =COUNTIF('LME Loan Type - Standard'!$I$7:$I$45,"Not Executed") | H8: =COUNTIF('LME Loan Type - Standard'!$I$7:$I$45,"Blocked")
A9: Loan Interest Rate | B9: Lending Management | C9: =COUNTA('LME Interest Rate'!$A$7:$A$53)-4 | D9: =COUNTIF('LME Interest Rate'!$H$7:$H$53,"Yes") | E9: =COUNTIF('LME Interest Rate'!$I$7:$I$53,"Passed") | F9: =COUNTIF('LME Interest Rate'!$I$7:$I$53,"Failed") | G9: =COUNTIF('LME Interest Rate'!$I$7:$I$53,"Not Executed") | H9: =COUNTIF('LME Interest Rate'!$I$7:$I$53,"Blocked")
A10: Loan Category | B10: Lending Management | C10: =COUNTA('LME Loan Category'!$A$7:$A$78)-4 | D10: =COUNTIF('LME Loan Category'!$H$7:$H$78,"Yes") | E10: =COUNTIF('LME Loan Category'!$I$7:$I$78,"Passed") | F10: =COUNTIF('LME Loan Category'!$I$7:$I$78,"Failed") | G10: =COUNTIF('LME Loan Category'!$I$7:$I$78,"Not Executed") | H10: =COUNTIF('LME Loan Category'!$I$7:$I$78,"Blocked")
A11: Loan Fee Type | B11: Lending Management | C11: =COUNTA('LME Loan Fee Type'!$A$7:$A$60)-4 | D11: =COUNTIF('LME Loan Fee Type'!$H$7:$H$60,"Yes") | E11: =COUNTIF('LME Loan Fee Type'!$I$7:$I$60,"Passed") | F11: =COUNTIF('LME Loan Fee Type'!$I$7:$I$60,"Failed") | G11: =COUNTIF('LME Loan Fee Type'!$I$7:$I$60,"Not Executed") | H11: =COUNTIF('LME Loan Fee Type'!$I$7:$I$60,"Blocked")
A12: Fee Capitalization | B12: Lending Management | C12: =COUNTA('LME Fee Capitalization'!$A$7:$A$96)-4 | D12: =COUNTIF('LME Fee Capitalization'!$H$7:$H$96,"Yes") | E12: =COUNTIF('LME Fee Capitalization'!$I$7:$I$96,"Passed") | F12: =COUNTIF('LME Fee Capitalization'!$I$7:$I$96,"Failed") | G12: =COUNTIF('LME Fee Capitalization'!$I$7:$I$96,"Not Executed") | H12: =COUNTIF('LME Fee Capitalization'!$I$7:$I$96,"Blocked")
A13: Loan Adjustment | B13: Lending Management | C13: =COUNTA('LME Loan Adjustment'!$A$7:$A$167)-4 | D13: =COUNTIF('LME Loan Adjustment'!$H$7:$H$167,"Yes") | E13: =COUNTIF('LME Loan Adjustment'!$I$7:$I$167,"Passed") | F13: =COUNTIF('LME Loan Adjustment'!$I$7:$I$167,"Failed") | G13: =COUNTIF('LME Loan Adjustment'!$I$7:$I$167,"Not Executed") | H13: =COUNTIF('LME Loan Adjustment'!$I$7:$I$167,"Blocked")
A14: Loan Write-Off | B14: Lending Management | C14: =COUNTA('LME Loan Write-Off'!$A$7:$A$85)-4 | D14: =COUNTIF('LME Loan Write-Off'!$H$7:$H$85,"Yes") | E14: =COUNTIF('LME Loan Write-Off'!$I$7:$I$85,"Passed") | F14: =COUNTIF('LME Loan Write-Off'!$I$7:$I$85,"Failed") | G14: =COUNTIF('LME Loan Write-Off'!$I$7:$I$85,"Not Executed") | H14: =COUNTIF('LME Loan Write-Off'!$I$7:$I$85,"Blocked")
A15: Loan Statements | B15: Lending Management | C15: =COUNTA('LME Statements'!$A$7:$A$52)-4 | D15: =COUNTIF('LME Statements'!$H$7:$H$52,"Yes") | E15: =COUNTIF('LME Statements'!$I$7:$I$52,"Passed") | F15: =COUNTIF('LME Statements'!$I$7:$I$52,"Failed") | G15: =COUNTIF('LME Statements'!$I$7:$I$52,"Not Executed") | H15: =COUNTIF('LME Statements'!$I$7:$I$52,"Blocked")
A16: Lending Workbench | B16: Lending Management | C16: =COUNTA('LME Workbench'!$A$7:$A$44) | D16: =COUNTIF('LME Workbench'!$H$7:$H$44,"Yes") | E16: =COUNTIF('LME Workbench'!$I$7:$I$44,"Passed") | F16: =COUNTIF('LME Workbench'!$I$7:$I$44,"Failed") | G16: =COUNTIF('LME Workbench'!$I$7:$I$44,"Not Executed") | H16: =COUNTIF('LME Workbench'!$I$7:$I$44,"Blocked")
A17: Loan Ledger Report | B17: Lending Management | C17: =COUNTA('LME Ledger Report'!$A$7:$A$92) | D17: =COUNTIF('LME Ledger Report'!$H$7:$H$92,"Yes") | E17: =COUNTIF('LME Ledger Report'!$I$7:$I$92,"Passed") | F17: =COUNTIF('LME Ledger Report'!$I$7:$I$92,"Failed") | G17: =COUNTIF('LME Ledger Report'!$I$7:$I$92,"Not Executed") | H17: =COUNTIF('LME Ledger Report'!$I$7:$I$92,"Blocked")
A18: Roll Forward Report | B18: Lending Management | C18: =COUNTA('LME Roll Forward'!$A$7:$A$57) | D18: =COUNTIF('LME Roll Forward'!$H$7:$H$57,"Yes") | E18: =COUNTIF('LME Roll Forward'!$I$7:$I$57,"Passed") | F18: =COUNTIF('LME Roll Forward'!$I$7:$I$57,"Failed") | G18: =COUNTIF('LME Roll Forward'!$I$7:$I$57,"Not Executed") | H18: =COUNTIF('LME Roll Forward'!$I$7:$I$57,"Blocked")
A19: Loan Payment | B19: Lending Management | C19: =COUNTA('LME Loan Payment from depositor'!$A$7:$A$99)-4 | D19: =COUNTIF('LME Loan Payment from depositor'!$H$7:$H$99,"Yes") | E19: =COUNTIF('LME Loan Payment from depositor'!$I$7:$I$99,"Passed") | F19: =COUNTIF('LME Loan Payment from depositor'!$I$7:$I$99,"Failed") | G19: =COUNTIF('LME Loan Payment from depositor'!$I$7:$I$99,"Not Executed") | H19: =COUNTIF('LME Loan Payment from depositor'!$I$7:$I$99,"Blocked")
A20: Overpayment | B20: Lending Management | C20: =COUNTA('LME Overpayment'!$A$7:$A$88)-4 | D20: =COUNTIF('LME Overpayment'!$H$7:$H$88,"Yes") | E20: =COUNTIF('LME Overpayment'!$I$7:$I$88,"Passed") | F20: =COUNTIF('LME Overpayment'!$I$7:$I$88,"Failed") | G20: =COUNTIF('LME Overpayment'!$I$7:$I$88,"Not Executed") | H20: =COUNTIF('LME Overpayment'!$I$7:$I$88,"Blocked")
A21: AR Payment | B21: Lending Management | C21: =COUNTA('LME AR Payment'!$A$7:$A$14) | D21: =COUNTIF('LME AR Payment'!$H$7:$H$14,"Yes") | E21: =COUNTIF('LME AR Payment'!$I$7:$I$14,"Passed") | F21: =COUNTIF('LME AR Payment'!$I$7:$I$14,"Failed") | G21: =COUNTIF('LME AR Payment'!$I$7:$I$14,"Not Executed") | H21: =COUNTIF('LME AR Payment'!$I$7:$I$14,"Blocked")
A22: Account | B22: Depository Management | C22: =COUNTA('DMS Account'!$A$7:$A$150)-4 | D22: =COUNTIF('DMS Account'!$H$7:$H$150,"Yes") | E22: =COUNTIF('DMS Account'!$I$7:$I$150,"Passed") | F22: =COUNTIF('DMS Account'!$I$7:$I$150,"Failed") | G22: =COUNTIF('DMS Account'!$I$7:$I$150,"Not Executed") | H22: =COUNTIF('DMS Account'!$I$7:$I$150,"Blocked")
A23: Account Category | B23: Depository Management | C23: =COUNTA('DMS Account Category'!$A$7:$A$55)-4 | D23: =COUNTIF('DMS Account Category'!$H$7:$H$55,"Yes") | E23: =COUNTIF('DMS Account Category'!$I$7:$I$55,"Passed") | F23: =COUNTIF('DMS Account Category'!$I$7:$I$55,"Failed") | G23: =COUNTIF('DMS Account Category'!$I$7:$I$55,"Not Executed") | H23: =COUNTIF('DMS Account Category'!$I$7:$I$55,"Blocked")
A24: Interest Rate | B24: Depository Management | C24: =COUNTA('DMS Interest Rate'!$A$7:$A$41)-4 | D24: =COUNTIF('DMS Interest Rate'!$H$7:$H$41,"Yes") | E24: =COUNTIF('DMS Interest Rate'!$I$7:$I$41,"Passed") | F24: =COUNTIF('DMS Interest Rate'!$I$7:$I$41,"Failed") | G24: =COUNTIF('DMS Interest Rate'!$I$7:$I$41,"Not Executed") | H24: =COUNTIF('DMS Interest Rate'!$I$7:$I$41,"Blocked")
A25: Fee Type | B25: Depository Management | C25: =COUNTA('DMS Fee Type'!$A$7:$A$35)-4 | D25: =COUNTIF('DMS Fee Type'!$H$7:$H$35,"Yes") | E25: =COUNTIF('DMS Fee Type'!$I$7:$I$35,"Passed") | F25: =COUNTIF('DMS Fee Type'!$I$7:$I$35,"Failed") | G25: =COUNTIF('DMS Fee Type'!$I$7:$I$35,"Not Executed") | H25: =COUNTIF('DMS Fee Type'!$I$7:$I$35,"Blocked")
A26: Other Adjustment | B26: Depository Management | C26: =COUNTA('DMS Other Adj Type'!$A$7:$A$37)-4 | D26: =COUNTIF('DMS Other Adj Type'!$H$7:$H$37,"Yes") | E26: =COUNTIF('DMS Other Adj Type'!$I$7:$I$37,"Passed") | F26: =COUNTIF('DMS Other Adj Type'!$I$7:$I$37,"Failed") | G26: =COUNTIF('DMS Other Adj Type'!$I$7:$I$37,"Not Executed") | H26: =COUNTIF('DMS Other Adj Type'!$I$7:$I$37,"Blocked")
A27: Adjustment | B27: Depository Management | C27: =COUNTA('DMS Adjustment'!$A$7:$A$229)-4 | D27: =COUNTIF('DMS Adjustment'!$H$7:$H$229,"Yes") | E27: =COUNTIF('DMS Adjustment'!$I$7:$I$229,"Passed") | F27: =COUNTIF('DMS Adjustment'!$I$7:$I$229,"Failed") | G27: =COUNTIF('DMS Adjustment'!$I$7:$I$229,"Not Executed") | H27: =COUNTIF('DMS Adjustment'!$I$7:$I$229,"Blocked")
A28: Deposits | B28: Depository Management | C28: =COUNTA('DMS Deposits'!$A$7:$A$183)-4 | D28: =COUNTIF('DMS Deposits'!$H$7:$H$183,"Yes") | E28: =COUNTIF('DMS Deposits'!$I$7:$I$183,"Passed") | F28: =COUNTIF('DMS Deposits'!$I$7:$I$183,"Failed") | G28: =COUNTIF('DMS Deposits'!$I$7:$I$183,"Not Executed") | H28: =COUNTIF('DMS Deposits'!$I$7:$I$183,"Blocked")
A29: Withdrawal | B29: Depository Management | C29: =COUNTA('DMS Withdrawal'!$A$7:$A$203)-4 | D29: =COUNTIF('DMS Withdrawal'!$H$7:$H$203,"Yes") | E29: =COUNTIF('DMS Withdrawal'!$I$7:$I$203,"Passed") | F29: =COUNTIF('DMS Withdrawal'!$I$7:$I$203,"Failed") | G29: =COUNTIF('DMS Withdrawal'!$I$7:$I$203,"Not Executed") | H29: =COUNTIF('DMS Withdrawal'!$I$7:$I$203,"Blocked")
A30: Transfer | B30: Depository Management | C30: =COUNTA('DMS Transfer'!$A$7:$A$297)-4 | D30: =COUNTIF('DMS Transfer'!$H$7:$H$297,"Yes") | E30: =COUNTIF('DMS Transfer'!$I$7:$I$297,"Passed") | F30: =COUNTIF('DMS Transfer'!$I$7:$I$297,"Failed") | G30: =COUNTIF('DMS Transfer'!$I$7:$I$297,"Not Executed") | H30: =COUNTIF('DMS Transfer'!$I$7:$I$297,"Blocked")
A31: Close Account | B31: Depository Management | C31: =COUNTA('DMS Close Account'!$A$7:$A$93)-4 | D31: =COUNTIF('DMS Close Account'!$H$7:$H$93,"Yes") | E31: =COUNTIF('DMS Close Account'!$I$7:$I$93,"Passed") | F31: =COUNTIF('DMS Close Account'!$I$7:$I$93,"Failed") | G31: =COUNTIF('DMS Close Account'!$I$7:$I$93,"Not Executed") | H31: =COUNTIF('DMS Close Account'!$I$7:$I$93,"Blocked")
A32: Statements | B32: Depository Management
A33: TOTAL | C33: =SUM(C5:C32) | D33: =SUM(D5:D32) | E33: =SUM(E5:E32) | F33: =SUM(F5:F32) | G33: =SUM(G5:G32) | H33: =SUM(H5:H32)
A35: Scope and usage notes
A36: 1. All test-case sheets use the exact 10 requested columns.
A37: 2. Status defaults to Not Executed; IS Automated defaults to TBD until the automation inventory is approved.
A38: 3. Existing scenarios were normalized from the supplied regression/test-case workbooks; prior execution results and defect commentary were intentionally not carried into the client baseline.
A39: 4. New Deposits, Withdrawal, Transfer, Close Depository Account, Statements, and Lending Overpayment cases are requirement-based design coverage. Jira references are marked TBD until approved requirement keys are supplied.
A40: 5. Items whose behavior depends on product policy (for example cross-currency transfers, account reopening, and overpayment disposition/allocation) are flagged in Comments for client confirmation.

Sheet LME Loan Account
A1: Lending - Loan Account
A2: Common Preconditions | C2: 1. User is signed in to Sage Intacct. 2. The correct Lending Management or Depository Management entity is selected. 3. The module is enabled for the company. 4. The user has the permission required for the scenario. 5. Required master/configuration records are active and available.
A4: Navigation: Applications > Lending Management > Loan account | Client baseline | 133 test cases | Updated 2026-08-27
A6: Test Case ID | B6: Test Scenario | C6: Preconditions | D6: Test Data | E6: Test Steps | F6: Expected Result | G6: Requirement/Jira Reference | H6: IS Automated | I6: Status | J6: Comments
A7: CREATE (54 test cases)
A8: LME-LA-001 | B8: Loan information section present | C8: Refer to Common Preconditions above. | D8: Account category: QA Loan Category Account number: LA-QA-001 User role: Full Access | E8: 1. Sign in to Sage Intacct with the test user. 2. Navigate to Applications > Lending Management > Loan account. 3. Open the page or record relevant to the scenario. 4. Perform the scenario action: Loan information section present. 5. Apply or complete the action where applicable. 6. Observe the page, messages, saved data, balances, and related records as applicable. | F8: Section heading visible | G8: TEST_CASES_Loan_Account.xlsx / TC-LA-002 | H8: TBD | I8: Not Executed | J8: Source section: B. Create page (IDs: TC-LA-001–058)
A9: LME-LA-002 | B9: Loan information fields present | C9: Refer to Common Preconditions above. | D9: Account category: QA Loan Category Account number: LA-QA-001 Account name: Client QA Loan 001 Customer: 1--Power Aerospace Materials Loan type: QA Non-Revolving Interest rate: 5.0000% Origination amount: 10000.00 Origination date: 2026-08-01 | E9: 1. Sign in to Sage Intacct with the test user. 2. Navigate to Applications > Lending Management > Loan account. 3. Open the page or record relevant to the scenario. 4. Perform the scenario action: Loan information fields present. 5. Apply or complete the action where applicable. 6. Observe the page, messages, saved data, balances, and related records as applicable. | F9: Account category/number/name, Customer, Vendor, Attachment, Description, Email statements, Amount all present | G9: TEST_CASES_Loan_Account.xlsx / TC-LA-003 | H9: TBD | I9: Not Executed | J9: Source section: B. Create page (IDs: TC-LA-001–058)
A10: LME-LA-003 | B10: Account category mandatory | C10: Refer to Common Preconditions above. | D10: Other required fields: Use the valid values listed below Target field: Blank Account category: QA Loan Category Account number: LA-QA-001 Account name: Client QA Loan 001 Customer: 1--Power Aerospace Materials | E10: 1. Sign in to Sage Intacct with the test user. 2. Navigate to Applications > Lending Management > Loan account. 3. Open the page or record relevant to the scenario. 4. Perform the scenario action: Account category mandatory. 5. Apply or complete the action where applicable. 6. Observe the page, messages, saved data, balances, and related records as applicable. | F10: Red asterisk shown | G10: TEST_CASES_Loan_Account.xlsx / TC-LA-004 | H10: TBD | I10: Not Executed | J10: Source section: B. Create page (IDs: TC-LA-001–058)
A11: LME-LA-004 | B11: Empty Account category error | C11: Refer to Common Preconditions above. | D11: Other required fields: Use the valid values listed below Target field: Blank Account category: QA Loan Category Account number: LA-QA-001 Account name: Client QA Loan 001 Customer: 1--Power Aerospace Materials | E11: 1. Sign in to Sage Intacct with the test user. 2. Navigate to Applications > Lending Management > Loan account. 3. Open the page or record relevant to the scenario. 4. Perform the scenario action: Empty Account category error. 5. Apply or complete the action where applicable. 6. Observe the page, messages, saved data, balances, and related records as applicable. | F11: "Account category is required for loan account." | G11: TEST_CASES_Loan_Account.xlsx / TC-LA-005 | H11: TBD | I11: Not Executed | J11: Source section: B. Create page (IDs: TC-LA-001–058)
A12: LME-LA-005 | B12: Account number mandatory | C12: Refer to Common Preconditions above. | D12: Other required fields: Use the valid values listed below Target field: Blank Account category: QA Loan Category Account number: LA-QA-001 Account name: Client QA Loan 001 Customer: 1--Power Aerospace Materials | E12: 1. Sign in to Sage Intacct with the test user. 2. Navigate to Applications > Lending Management > Loan account. 3. Open the page or record relevant to the scenario. 4. Perform the scenario action: Account number mandatory. 5. Apply or complete the action where applicable. 6. Observe the page, messages, saved data, balances, and related records as applicable. | F12: Red asterisk shown | G12: TEST_CASES_Loan_Account.xlsx / TC-LA-006 | H12: TBD | I12: Not Executed | J12: Source section: B. Create page (IDs: TC-LA-001–058)
A13: LME-LA-006 | B13: Empty Account number (no-sequence category) | C13: Refer to Common Preconditions above. | D13: Other required fields: Use the valid values listed below Target field: Blank Account category: QA Loan Category Account number: LA-QA-001 Account name: Client QA Loan 001 Customer: 1--Power Aerospace Materials | E13: 1. Sign in to Sage Intacct with the test user. 2. Navigate to Applications > Lending Management > Loan account. 3. Open the page or record relevant to the scenario. 4. Perform the scenario action: Empty Account number (no-sequence category). 5. Apply or complete the action where applicable. 6. Observe the page, messages, saved data, balances, and related records as applicable. | F13: Friendly error, no object-path leak (fixed) | G13: TEST_CASES_Loan_Account.xlsx / TC-LA-008 | H13: TBD | I13: Not Executed | J13: Source section: B. Create page (IDs: TC-LA-001–058)
A14: LME-LA-007 | B14: Account name mandatory | C14: Refer to Common Preconditions above. | D14: Other required fields: Use the valid values listed below Target field: Blank Account category: QA Loan Category Account number: LA-QA-001 Account name: Client QA Loan 001 Customer: 1--Power Aerospace Materials | E14: 1. Sign in to Sage Intacct with the test user. 2. Navigate to Applications > Lending Management > Loan account. 3. Open the page or record relevant to the scenario. 4. Perform the scenario action: Account name mandatory. 5. Apply or complete the action where applicable. 6. Observe the page, messages, saved data, balances, and related records as applicable. | F14: Red asterisk shown | G14: TEST_CASES_Loan_Account.xlsx / TC-LA-009 | H14: TBD | I14: Not Executed | J14: Source section: B. Create page (IDs: TC-LA-001–058)
A15: LME-LA-008 | B15: Empty Account name error | C15: Refer to Common Preconditions above. | D15: Other required fields: Use the valid values listed below Target field: Blank Account category: QA Loan Category Account number: LA-QA-001 Account name: Client QA Loan 001 Customer: 1--Power Aerospace Materials | E15: 1. Sign in to Sage Intacct with the test user. 2. Navigate to Applications > Lending Management > Loan account. 3. Open the page or record relevant to the scenario. 4. Perform the scenario action: Empty Account name error. 5. Apply or complete the action where applicable. 6. Observe the page, messages, saved data, balances, and related records as applicable. | F15: "Account name is required for loan account." | G15: TEST_CASES_Loan_Account.xlsx / TC-LA-010 | H15: TBD | I15: Not Executed | J15: Source section: B. Create page (IDs: TC-LA-001–058)
A16: LME-LA-009 | B16: Account name >200 chars rejected | C16: Refer to Common Preconditions above. | D16: Account category: QA Loan Category Account number: LA-QA-001 Account name: Client QA Loan 001 Customer: 1--Power Aerospace Materials Loan type: QA Non-Revolving Interest rate: 5.0000% Origination amount: 10000.00 Origination date: 2026-08-01 | E16: 1. Sign in to Sage Intacct with the test user. 2. Navigate to Applications > Lending Management > Loan account. 3. Open the page or record relevant to the scenario. 4. Perform the scenario action: Account name >200 chars rejected. 5. Apply or complete the action where applicable. 6. Observe the page, messages, saved data, balances, and related records as applicable. | F16: Friendly message, no raw i18n key (fixed) | G16: TEST_CASES_Loan_Account.xlsx / TC-LA-011 | H16: TBD | I16: Not Executed | J16: Source section: B. Create page (IDs: TC-LA-001–058)
A17: LME-LA-010 | B17: Customer mandatory | C17: Refer to Common Preconditions above. | D17: Other required fields: Use the valid values listed below Target field: Blank Account category: QA Loan Category Account number: LA-QA-001 Account name: Client QA Loan 001 Customer: 1--Power Aerospace Materials | E17: 1. Sign in to Sage Intacct with the test user. 2. Navigate to Applications > Lending Management > Loan account. 3. Open the page or record relevant to the scenario. 4. Perform the scenario action: Customer mandatory. 5. Apply or complete the action where applicable. 6. Observe the page, messages, saved data, balances, and related records as applicable. | F17: Red asterisk shown | G17: TEST_CASES_Loan_Account.xlsx / TC-LA-012 | H17: TBD | I17: Not Executed | J17: Source section: B. Create page (IDs: TC-LA-001–058)
A18: LME-LA-011 | B18: Empty Customer error | C18: Refer to Common Preconditions above. | D18: Other required fields: Use the valid values listed below Target field: Blank Account category: QA Loan Category Account number: LA-QA-001 Account name: Client QA Loan 001 Customer: 1--Power Aerospace Materials | E18: 1. Sign in to Sage Intacct with the test user. 2. Navigate to Applications > Lending Management > Loan account. 3. Open the page or record relevant to the scenario. 4. Perform the scenario action: Empty Customer error. 5. Apply or complete the action where applicable. 6. Observe the page, messages, saved data, balances, and related records as applicable. | F18: "Customer is required for loan account." | G18: TEST_CASES_Loan_Account.xlsx / TC-LA-013 | H18: TBD | I18: Not Executed | J18: Source section: B. Create page (IDs: TC-LA-001–058)
A19: LME-LA-012 | B19: Vendor mandatory | C19: Refer to Common Preconditions above. | D19: Other required fields: Use the valid values listed below Target field: Blank Account category: QA Loan Category Account number: LA-QA-001 Account name: Client QA Loan 001 Customer: 1--Power Aerospace Materials | E19: 1. Sign in to Sage Intacct with the test user. 2. Navigate to Applications > Lending Management > Loan account. 3. Open the page or record relevant to the scenario. 4. Perform the scenario action: Vendor mandatory. 5. Apply or complete the action where applicable. 6. Observe the page, messages, saved data, balances, and related records as applicable. | F19: Red asterisk shown | G19: TEST_CASES_Loan_Account.xlsx / TC-LA-014 | H19: TBD | I19: Not Executed | J19: Source section: B. Create page (IDs: TC-LA-001–058)
... A29: LME-LA-022 | B29: Empty Interest rate error | C29: Refer to Common Preconditions above. | D29: Other required fields: Use the valid values listed below Target field: Blank Account category: QA Loan Category Account number: LA-QA-001 Account name: Client QA Loan 001 Customer: 1--Power Aerospace Materials | E29: 1. Sign in to Sage Intacct with the test user. 2. Navigate to Applications > Lending Management > Loan account. 3. Open the page or record relevant to the scenario. 4. Perform the scenario action: Empty Interest rate error. 5. Apply or complete the action where applicable. 6. Observe the page, messages, saved data, balances, and related records as applicable. | F29: Friendly "Interest rate is required..." (fixed, was NPE) | G29: TEST_CASES_Loan_Account.xlsx / TC-LA-024 | H29: TBD | I29: Not Executed | J29: Source section: B. Create page (IDs: TC-LA-001–058)
A30: LME-LA-023 | B30: Non-revolving reveals Term/First payment fields | C30: Refer to Common Preconditions above. | E30: 1. Sign in to Sage Intacct with the test user. 2. Navigate to Applications > Lending Management > Loan account. 3. Open the page or record relevant to the scenario. 4. Perform the scenario action: Non-revolving reveals Term/First payment fields. 5. Apply or complete the action where applicable. 6. Observe the page, messages, saved data, balances, and related records as applicable. | F30: Fields + Preview link visible | G30: TEST_CASES_Loan_Account.xlsx / TC-LA-025 | H30: TBD | I30: Not Executed | J30: Source section: B. Create page (IDs: TC-LA-001–058)
A31: LME-LA-024 | B31: Revolving reveals amortization checkbox | C31: Refer to Common Preconditions above. | D31: Account category: QA Loan Category Account number: LA-QA-001 Account name: Client QA Loan 001 Customer: 1--Power Aerospace Materials Loan type: QA Non-Revolving Interest rate: 5.0000% Origination amount: 10000.00 Origination date: 2026-08-01 | E31: 1. Sign in to Sage Intacct with the test user. 2. Navigate to Applications > Lending Management > Loan account. 3. Open the page or record relevant to the scenario. 4. Perform the scenario action: Revolving reveals amortization checkbox. 5. Apply or complete the action where applicable. 6. Observe the page, messages, saved data, balances, and related records as applicable. | F31: Checkbox + Renewal date visible | G31: TEST_CASES_Loan_Account.xlsx / TC-LA-026 | H31: TBD | I31: Not Executed | J31: Source section: B. Create page (IDs: TC-LA-001–058)
A32: LME-LA-025 | B32: Valid Non-revolving save succeeds | C32: Refer to Common Preconditions above. | D32: Account category: QA Loan Category Account number: LA-QA-001 Account name: Client QA Loan 001 Customer: 1--Power Aerospace Materials Loan type: QA Non-Revolving Interest rate: 5.0000% Origination amount: 10000.00 Origination date: 2026-08-01 | E32: 1. Sign in to Sage Intacct with the test user. 2. Navigate to Applications > Lending Management > Loan account. 3. Open the page or record relevant to the scenario. 4. Perform the scenario action: Valid Non-revolving save succeeds. 5. Click Save or the applicable submit action. 6. Observe the page, messages, saved data, balances, and related records as applicable. | F32: Redirects to View page | G32: TEST_CASES_Loan_Account.xlsx / TC-LA-027 | H32: TBD | I32: Not Executed | J32: Source section: B. Create page (IDs: TC-LA-001–058)
A33: LME-LA-026 | B33: [KNOWN DEFECT] Revolving+amortization save crashes | C33: Refer to Common Preconditions above. | D33: Account category: QA Loan Category Account number: LA-QA-001 Account name: Client QA Loan 001 Customer: 1--Power Aerospace Materials Loan type: QA Non-Revolving Interest rate: 5.0000% Origination amount: 10000.00 Origination date: 2026-08-01 | E33: 1. Sign in to Sage Intacct with the test user. 2. Navigate to Applications > Lending Management > Loan account. 3. Open the page or record relevant to the scenario. 4. Perform the scenario action: [KNOWN DEFECT] Revolving+amortization save crashes. 5. Click Save or the applicable submit action. 6. Observe the page, messages, saved data, balances, and related records as applicable. | F33: Raw exception toasts, stays on Create | G33: TEST_CASES_Loan_Account.xlsx / TC-LA-028 | H33: TBD | I33: Not Executed | J33: Source section: B. Create page (IDs: TC-LA-001–058)
A34: LME-LA-027 | B34: Preview amortization schedule modal | C34: Refer to Common Preconditions above. | D34: Account category: QA Loan Category Account number: LA-QA-001 Account name: Client QA Loan 001 Customer: 1--Power Aerospace Materials Loan type: QA Non-Revolving Interest rate: 5.0000% Origination amount: 10000.00 Origination date: 2026-08-01 | E34: 1. Sign in to Sage Intacct with the test user. 2. Navigate to Applications > Lending Management > Loan account. 3. Open the page or record relevant to the scenario. 4. Perform the scenario action: Preview amortization schedule modal. 5. Apply or complete the action where applicable. 6. Observe the page, messages, saved data, balances, and related records as applicable. | F34: Populated table with expected columns | G34: TEST_CASES_Loan_Account.xlsx / TC-LA-029 | H34: TBD | I34: Not Executed | J34: Source section: B. Create page (IDs: TC-LA-001–058)
A35: LME-LA-028 | B35: Amount mandatory numeric | C35: Refer to Common Preconditions above. | D35: Other required fields: Use the valid values listed below Target field: Blank | E35: 1. Sign in to Sage Intacct with the test user. 2. Navigate to Applications > Lending Management > Loan account. 3. Open the page or record relevant to the scenario. 4. Perform the scenario action: Amount mandatory numeric. 5. Apply or complete the action where applicable. 6. Observe the page, messages, saved data, balances, and related records as applicable. | F35: Red asterisk shown | G35: TEST_CASES_Loan_Account.xlsx / TC-LA-030 | H35: TBD | I35: Not Executed | J35: Source section: B. Create page (IDs: TC-LA-001–058)
A36: LME-LA-029 | B36: Empty Amount error | C36: Refer to Common Preconditions above. | D36: Other required fields: Use the valid values listed below Target field: Blank | E36: 1. Sign in to Sage Intacct with the test user. 2. Navigate to Applications > Lending Management > Loan account. 3. Open the page or record relevant to the scenario. 4. Perform the scenario action: Empty Amount error. 5. Apply or complete the action where applicable. 6. Observe the page, messages, saved data, balances, and related records as applicable. | F36: "Amount is required for loan account." | G36: TEST_CASES_Loan_Account.xlsx / TC-LA-031 | H36: TBD | I36: Not Executed | J36: Source section: B. Create page (IDs: TC-LA-001–058)
A37: LME-LA-030 | B37: Negative Amount rejected | C37: Refer to Common Preconditions above. | D37: Amount: -1.00 | E37: 1. Sign in to Sage Intacct with the test user. 2. Navigate to Applications > Lending Management > Loan account. 3. Open the page or record relevant to the scenario. 4. Perform the scenario action: Negative Amount rejected. 5. Apply or complete the action where applicable. 6. Observe the page, messages, saved data, balances, and related records as applicable. | F37: Friendly message, no /originationAmount leak (fixed) | G37: TEST_CASES_Loan_Account.xlsx / TC-LA-032 | H37: TBD | I37: Not Executed | J37: Source section: B. Create page (IDs: TC-LA-001–058)
A38: LME-LA-031 | B38: Amount = 0 accepted | C38: Refer to Common Preconditions above. | E38: 1. Sign in to Sage Intacct with the test user. 2. Navigate to Applications > Lending Management > Loan account. 3. Open the page or record relevant to the scenario. 4. Perform the scenario action: Amount = 0 accepted. 5. Apply or complete the action where applicable. 6. Observe the page, messages, saved data, balances, and related records as applicable. | F38: Record created | G38: TEST_CASES_Loan_Account.xlsx / TC-LA-033 | H38: TBD | I38: Not Executed | J38: Source section: B. Create page (IDs: TC-LA-001–058)
A39: LME-LA-032 | B39: Dimensions section fields present | C39: Refer to Common Preconditions above. | D39: Account category: QA Loan Category Account number: LA-QA-001 User role: Full Access | E39: 1. Sign in to Sage Intacct with the test user. 2. Navigate to Applications > Lending Management > Loan account. 3. Open the page or record relevant to the scenario. 4. Perform the scenario action: Dimensions section fields present. 5. Apply or complete the action where applicable. 6. Observe the page, messages, saved data, balances, and related records as applicable. | F39: Department, Location, Project, Employee, Item, Class, Contract | G39: TEST_CASES_Loan_Account.xlsx / TC-LA-034 | H39: TBD | I39: Not Executed | J39: Source section: B. Create page (IDs: TC-LA-001–058)
A40: LME-LA-033 | B40: Non-Location dimensions not mandatory | C40: Refer to Common Preconditions above. | D40: Other required fields: Use the valid values listed below Target field: Blank Account category: QA Loan Category Account number: LA-QA-001 Account name: Client QA Loan 001 Customer: 1--Power Aerospace Materials | E40: 1. Sign in to Sage Intacct with the test user. 2. Navigate to Applications > Lending Management > Loan account. 3. Open the page or record relevant to the scenario. 4. Perform the scenario action: Non-Location dimensions not mandatory. 5. Apply or complete the action where applicable. 6. Observe the page, messages, saved data, balances, and related records as applicable. | F40: No asterisk on Department/Project/Class/Item | G40: TEST_CASES_Loan_Account.xlsx / TC-LA-035 | H40: TBD | I40: Not Executed | J40: Source section: B. Create page (IDs: TC-LA-001–058)
A41: LME-LA-034 | B41: [KNOWN DEFECT] Location has no asterisk | C41: Refer to Common Preconditions above. | D41: Account category: QA Loan Category Account number: LA-QA-001 Account name: Client QA Loan 001 Customer: 1--Power Aerospace Materials Loan type: QA Non-Revolving Interest rate: 5.0000% Origination amount: 10000.00 Origination date: 2026-08-01 | E41: 1. Sign in to Sage Intacct with the test user. 2. Navigate to Applications > Lending Management > Loan account. 3. Open the page or record relevant to the scenario. 4. Perform the scenario action: [KNOWN DEFECT] Location has no asterisk. 5. Apply or complete the action where applicable. 6. Observe the page, messages, saved data, balances, and related records as applicable. | F41: Missing despite being enforced | G41: TEST_CASES_Loan_Account.xlsx / TC-LA-036 | H41: TBD | I41: Not Executed | J41: Source section: B. Create page (IDs: TC-LA-001–058)
A42: LME-LA-035 | B42: Empty Location error | C42: Refer to Common Preconditions above. | D42: Other required fields: Use the valid values listed below Target field: Blank Account category: QA Loan Category Account number: LA-QA-001 Account name: Client QA Loan 001 Customer: 1--Power Aerospace Materials | E42: 1. Sign in to Sage Intacct with the test user. 2. Navigate to Applications > Lending Management > Loan account. 3. Open the page or record relevant to the scenario. 4. Perform the scenario action: Empty Location error. 5. Apply or complete the action where applicable. 6. Observe the page, messages, saved data, balances, and related records as applicable. | F42: "Location is required for loan account." | G42: TEST_CASES_Loan_Account.xlsx / TC-LA-037 | H42: TBD | I42: Not Executed | J42: Source section: B. Create page (IDs: TC-LA-001–058)
A43: LME-LA-036 | B43: Valid Location succeeds | C43: Refer to Common Preconditions above. | D43: Account category: QA Loan Category Account number: LA-QA-001 Account name: Client QA Loan 001 Customer: 1--Power Aerospace Materials Loan type: QA Non-Revolving Interest rate: 5.0000% Origination amount: 10000.00 Origination date: 2026-08-01 | E43: 1. Sign in to Sage Intacct with the test user. 2. Navigate to Applications > Lending Management > Loan account. 3. Open the page or record relevant to the scenario. 4. Perform the scenario action: Valid Location succeeds. 5. Apply or complete the action where applicable. 6. Observe the page, messages, saved data, balances, and related records as applicable. | F43: Record created | G43: TEST_CASES_Loan_Account.xlsx / TC-LA-038 | H43: TBD | I43: Not Executed | J43: Source section: B. Create page (IDs: TC-LA-001–058)
A44: LME-LA-037 | B44: Save split-button options | C44: Refer to Common Preconditions above. | D44: Account category: QA Loan Category Account number: LA-QA-001 Account name: Client QA Loan 001 Customer: 1--Power Aerospace Materials Loan type: QA Non-Revolving Interest rate: 5.0000% Origination amount: 10000.00 Origination date: 2026-08-01 | E44: 1. Sign in to Sage Intacct with the test user. 2. Navigate to Applications > Lending Management > Loan account. 3. Open the page or record relevant to the scenario. 4. Perform the scenario action: Save split-button options. 5. Click Save or the applicable submit action. 6. Observe the page, messages, saved data, balances, and related records as applicable. | F44: Save, Save and close, Save and new | G44: TEST_CASES_Loan_Account.xlsx / TC-LA-039 | H44: TBD | I44: Not Executed | J44: Source section: B. Create page (IDs: TC-LA-001–058)
A45: LME-LA-038 | B45: Success message on valid save | C45: Refer to Common Preconditions above. | D45: Account category: QA Loan Category Account number: LA-QA-001 Account name: Client QA Loan 001 Customer: 1--Power Aerospace Materials Loan type: QA Non-Revolving Interest rate: 5.0000% Origination amount: 10000.00 Origination date: 2026-08-01 | E45: 1. Sign in to Sage Intacct with the test user. 2. Navigate to Applications > Lending Management > Loan account. 3. Open the page or record relevant to the scenario. 4. Perform the scenario action: Success message on valid save. 5. Click Save or the applicable submit action. 6. Observe the page, messages, saved data, balances, and related records as applicable. | F45: Toast/redirect confirms | G45: TEST_CASES_Loan_Account.xlsx / TC-LA-041 | H45: TBD | I45: Not Executed | J45: Source section: B. Create page (IDs: TC-LA-001–058)
A46: LME-LA-039 | B46: Validation errors show banner + inline | C46: Refer to Common Preconditions above. | D46: Account category: QA Loan Category Account number: LA-QA-001 Account name: Client QA Loan 001 Customer: 1--Power Aerospace Materials Loan type: QA Non-Revolving Interest rate: 5.0000% Origination amount: 10000.00 Origination date: 2026-08-01 | E46: 1. Sign in to Sage Intacct with the test user. 2. Navigate to Applications > Lending Management > Loan account. 3. Open the page or record relevant to the scenario. 4. Perform the scenario action: Validation errors show banner + inline. 5. Apply or complete the action where applicable. 6. Observe the page, messages, saved data, balances, and related records as applicable. | F46: Both present | G46: TEST_CASES_Loan_Account.xlsx / TC-LA-042 | H46: TBD | I46: Not Executed | J46: Source section: B. Create page (IDs: TC-LA-001–058)
A47: LME-LA-040 | B47: Account category dropdown active-only | C47: Refer to Common Preconditions above. | D47: Account category: QA Loan Category Account number: LA-QA-001 Account name: Client QA Loan 001 Customer: 1--Power Aerospace Materials Loan type: QA Non-Revolving Interest rate: 5.0000% Origination amount: 10000.00 Origination date: 2026-08-01 | E47: 1. Sign in to Sage Intacct with the test user. 2. Navigate to Applications > Lending Management > Loan account. 3. Open the page or record relevant to the scenario. 4. Perform the scenario action: Account category dropdown active-only. 5. Apply or complete the action where applicable. 6. Observe the page, messages, saved data, balances, and related records as applicable. | F47: Active category found | G47: TEST_CASES_Loan_Account.xlsx / TC-LA-043 | H47: TBD | I47: Not Executed | J47: Source section: B. Create page (IDs: TC-LA-001–058)
A48: LME-LA-041 | B48: Customer dropdown active-only | C48: Refer to Common Preconditions above. | D48: Account category: QA Loan Category Account number: LA-QA-001 Account name: Client QA Loan 001 Customer: 1--Power Aerospace Materials Loan type: QA Non-Revolving Interest rate: 5.0000% Origination amount: 10000.00 Origination date: 2026-08-01 | E48: 1. Sign in to Sage Intacct with the test user. 2. Navigate to Applications > Lending Management > Loan account. 3. Open the page or record relevant to the scenario. 4. Perform the scenario action: Customer dropdown active-only. 5. Apply or complete the action where applicable. 6. Observe the page, messages, saved data, balances, and related records as applicable. | F48: Active customer found | G48: TEST_CASES_Loan_Account.xlsx / TC-LA-044 | H48: TBD | I48: Not Executed | J48: Source section: B. Create page (IDs: TC-LA-001–058)
A49: LME-LA-042 | B49: Vendor dropdown active-only | C49: Refer to Common Preconditions above. | D49: Account category: QA Loan Category Account number: LA-QA-001 Account name: Client QA Loan 001 Customer: 1--Power Aerospace Materials Loan type: QA Non-Revolving Interest rate: 5.0000% Origination amount: 10000.00 Origination date: 2026-08-01 | E49: 1. Sign in to Sage Intacct with the test user. 2. Navigate to Applications > Lending Management > Loan account. 3. Open the page or record relevant to the scenario. 4. Perform the scenario action: Vendor dropdown active-only. 5. Apply or complete the action where applicable. 6. Observe the page, messages, saved data, balances, and related records as applicable. | F49: Active vendor found | G49: TEST_CASES_Loan_Account.xlsx / TC-LA-045 | H49: TBD | I49: Not Executed | J49: Source section: B. Create page (IDs: TC-LA-001–058)
A50: LME-LA-043 | B50: Empty Description accepted | C50: Refer to Common Preconditions above. | D50: Description: Client QA test text Other required fields: Use the valid values listed below Target field: Blank Account category: QA Loan Category Account number: LA-QA-001 Account name: Client QA Loan 001 Customer: 1--Power Aerospace Materials | E50: 1. Sign in to Sage Intacct with the test user. 2. Navigate to Applications > Lending Management > Loan account. 3. Open the page or record relevant to the scenario. 4. Perform the scenario action: Empty Description accepted. 5. Apply or complete the action where applicable. 6. Observe the page, messages, saved data, balances, and related records as applicable. | F50: View shows "--" | G50: TEST_CASES_Loan_Account.xlsx / TC-LA-047 | H50: TBD | I50: Not Executed | J50: Source section: B. Create page (IDs: TC-LA-001–058)
... A61: LME-LA-054 | B61: Whitespace Account name rejected | C61: Refer to Common Preconditions above. | D61: Account category: QA Loan Category Account number: LA-QA-001 Account name: Client QA Loan 001 Customer: 1--Power Aerospace Materials Loan type: QA Non-Revolving Interest rate: 5.0000% Origination amount: 10000.00 Origination date: 2026-08-01 | E61: 1. Sign in to Sage Intacct with the test user. 2. Navigate to Applications > Lending Management > Loan account. 3. Open the page or record relevant to the scenario. 4. Perform the scenario action: Whitespace Account name rejected. 5. Apply or complete the action where applicable. 6. Observe the page, messages, saved data, balances, and related records as applicable. | F61: Friendly message (fixed) | G61: TEST_CASES_Loan_Account.xlsx / TC-LA-058 | H61: TBD | I61: Not Executed | J61: Source section: B. Create page (IDs: TC-LA-001–058)
...

Sheet LME Loan Type
A1: Lending - Loan Type
A2: Common Preconditions | C2: 1. User is signed in to Sage Intacct. 2. The correct Lending Management or Depository Management entity is selected. 3. The module is enabled for the company. 4. The user has the permission required for the scenario. 5. Required master/configuration records are active and available.
A4: Navigation: Applications > Lending Management > Loan type | Client baseline | 67 test cases | Updated 2026-08-27
A6: Test Case ID | B6: Test Scenario | C6: Preconditions | D6: Test Data | E6: Test Steps | F6: Expected Result | G6: Requirement/Jira Reference | H6: IS Automated | I6: Status | J6: Comments
A7: CREATE (21 test cases)
A8: LME-LT-001 | B8: Loan type name field present | C8: Refer to Common Preconditions above. | D8: Name: QA Non-Revolving Loan Type Type: Non-revolving Interest calculation method: Simple Description: Client QA loan type | E8: 1. Sign in to Sage Intacct with the test user. 2. Navigate to Applications > Lending Management > Loan type. 3. Open the page or record relevant to the scenario. 4. Perform the scenario action: Loan type name field present. 5. Apply or complete the action where applicable. 6. Observe the page, messages, saved data, balances, and related records as applicable. | F8: Text input visible | G8: TEST_CASES_Loan_Type.xlsx / TC-LT-028 | H8: TBD | I8: Not Executed | J8: Source section: B. Create (IDs: TC-LT-028–046, TC-LT-057–066 new)
A9: LME-LT-002 | B9: Empty name blocked | C9: Refer to Common Preconditions above. | D9: Other required fields: Use the valid values listed below Target field: Blank Name: QA Non-Revolving Loan Type Type: Non-revolving Interest calculation method: Simple Description: Client QA loan type | E9: 1. Sign in to Sage Intacct with the test user. 2. Navigate to Applications > Lending Management > Loan type. 3. Open the page or record relevant to the scenario. 4. Perform the scenario action: Empty name blocked. 5. Apply or complete the action where applicable. 6. Observe the page, messages, saved data, balances, and related records as applicable. | F9: Validation error / stays on Create | G9: TEST_CASES_Loan_Type.xlsx / TC-LT-029 | H9: TBD | I9: Not Executed | J9: Source section: B. Create (IDs: TC-LT-028–046, TC-LT-057–066 new)
A10: LME-LT-003 | B10: Description optional | C10: Refer to Common Preconditions above. | D10: Name: QA Non-Revolving Loan Type Type: Non-revolving Interest calculation method: Simple Description: Client QA test text | E10: 1. Sign in to Sage Intacct with the test user. 2. Navigate to Applications > Lending Management > Loan type. 3. Open the page or record relevant to the scenario. 4. Perform the scenario action: Description optional. 5. Apply or complete the action where applicable. 6. Observe the page, messages, saved data, balances, and related records as applicable. | F10: No asterisk on label | G10: TEST_CASES_Loan_Type.xlsx / TC-LT-030 | H10: TBD | I10: Not Executed | J10: Source section: B. Create (IDs: TC-LT-028–046, TC-LT-057–066 new)
A11: LME-LT-004 | B11: Type defaults visible | C11: Refer to Common Preconditions above. | D11: Name: QA Non-Revolving Loan Type Type: Non-revolving Interest calculation method: Simple Description: Client QA loan type | E11: 1. Sign in to Sage Intacct with the test user. 2. Navigate to Applications > Lending Management > Loan type. 3. Open the page or record relevant to the scenario. 4. Perform the scenario action: Type defaults visible. 5. Apply or complete the action where applicable. 6. Observe the page, messages, saved data, balances, and related records as applicable. | F11: Revolving/Non-revolving radios visible | G11: TEST_CASES_Loan_Type.xlsx / TC-LT-031 | H11: TBD | I11: Not Executed | J11: Source section: B. Create (IDs: TC-LT-028–046, TC-LT-057–066 new)
A12: LME-LT-005 | B12: Interest type options | C12: Refer to Common Preconditions above. | D12: Name: QA Non-Revolving Loan Type Type: Non-revolving Interest calculation method: Simple Description: Client QA loan type | E12: 1. Sign in to Sage Intacct with the test user. 2. Navigate to Applications > Lending Management > Loan type. 3. Open the page or record relevant to the scenario. 4. Perform the scenario action: Interest type options. 5. Apply or complete the action where applicable. 6. Observe the page, messages, saved data, balances, and related records as applicable. | F12: 'Simple' and 'Compound' both listed | G12: TEST_CASES_Loan_Type.xlsx / TC-LT-032 | H12: TBD | I12: Not Executed | J12: Source section: B. Create (IDs: TC-LT-028–046, TC-LT-057–066 new)
A13: LME-LT-006 | B13: Interest calculation method required | C13: Refer to Common Preconditions above. | D13: Other required fields: Use the valid values listed below Target field: Blank Name: QA Non-Revolving Loan Type Type: Non-revolving Interest calculation method: Simple Description: Client QA loan type | E13: 1. Sign in to Sage Intacct with the test user. 2. Navigate to Applications > Lending Management > Loan type. 3. Open the page or record relevant to the scenario. 4. Perform the scenario action: Interest calculation method required. 5. Apply or complete the action where applicable. 6. Observe the page, messages, saved data, balances, and related records as applicable. | F13: Appears (conditionally, after Type selected) with `*` | G13: TEST_CASES_Loan_Type.xlsx / TC-LT-033 | H13: TBD | I13: Not Executed | J13: Source section: B. Create (IDs: TC-LT-028–046, TC-LT-057–066 new)
A14: LME-LT-007 | B14: Interest calculation method options (Revolving) | C14: Refer to Common Preconditions above. | D14: Name: QA Non-Revolving Loan Type Type: Non-revolving Interest calculation method: Simple Description: Client QA loan type | E14: 1. Sign in to Sage Intacct with the test user. 2. Navigate to Applications > Lending Management > Loan type. 3. Open the page or record relevant to the scenario. 4. Perform the scenario action: Interest calculation method options (Revolving). 5. Apply or complete the action where applicable. 6. Observe the page, messages, saved data, balances, and related records as applicable. | F14: 'Actual/365' and 'Actual/360' listed | G14: TEST_CASES_Loan_Type.xlsx / TC-LT-034 | H14: TBD | I14: Not Executed | J14: Source section: B. Create (IDs: TC-LT-028–046, TC-LT-057–066 new)
A15: LME-LT-008 | B15: **[new]** Interest calculation method options (Non-revolving) | C15: Refer to Common Preconditions above. | D15: Name: QA Non-Revolving Loan Type Type: Non-revolving Interest calculation method: Simple Description: Client QA loan type | E15: 1. Sign in to Sage Intacct with the test user. 2. Navigate to Applications > Lending Management > Loan type. 3. Open the page or record relevant to the scenario. 4. Perform the scenario action: **[new]** Interest calculation method options (Non-revolving). 5. Apply or complete the action where applicable. 6. Observe the page, messages, saved data, balances, and related records as applicable. | F15: 'Actual/365', 'Actual/360', **and '30/360'** all listed (superset of Revolving's two) | G15: TEST_CASES_Loan_Type.xlsx / TC-LT-034b | H15: TBD | I15: Not Executed | J15: Source section: B. Create (IDs: TC-LT-028–046, TC-LT-057–066 new)
A16: LME-LT-009 | B16: Status defaults to Active | C16: Refer to Common Preconditions above. | D16: Name: QA Non-Revolving Loan Type Type: Non-revolving Interest calculation method: Simple Description: Client QA loan type | E16: 1. Sign in to Sage Intacct with the test user. 2. Navigate to Applications > Lending Management > Loan type. 3. Open the page or record relevant to the scenario. 4. Perform the scenario action: Status defaults to Active. 5. Apply or complete the action where applicable. 6. Observe the page, messages, saved data, balances, and related records as applicable. | F16: Confirmed on View after save (no Status field on Create itself) | G16: TEST_CASES_Loan_Type.xlsx / TC-LT-035 | H16: TBD | I16: Not Executed | J16: Source section: B. Create (IDs: TC-LT-028–046, TC-LT-057–066 new)
A17: LME-LT-010 | B17: Order Entry transaction definition required | C17: Refer to Common Preconditions above. | D17: Other required fields: Use the valid values listed below Target field: Blank Name: QA Non-Revolving Loan Type Type: Non-revolving Interest calculation method: Simple Description: Client QA loan type | E17: 1. Sign in to Sage Intacct with the test user. 2. Navigate to Applications > Lending Management > Loan type. 3. Open the page or record relevant to the scenario. 4. Perform the scenario action: Order Entry transaction definition required. 5. Apply or complete the action where applicable. 6. Observe the page, messages, saved data, balances, and related records as applicable. | F17: `*` next to label | G17: TEST_CASES_Loan_Type.xlsx / TC-LT-036 | H17: TBD | I17: Not Executed | J17: Source section: B. Create (IDs: TC-LT-028–046, TC-LT-057–066 new)
A18: LME-LT-011 | B18: Item for loan principal posting required | C18: Refer to Common Preconditions above. | D18: Other required fields: Use the valid values listed below Target field: Blank Name: QA Non-Revolving Loan Type Type: Non-revolving Interest calculation method: Simple Description: Client QA loan type | E18: 1. Sign in to Sage Intacct with the test user. 2. Navigate to Applications > Lending Management > Loan type. 3. Open the page or record relevant to the scenario. 4. Perform the scenario action: Item for loan principal posting required. 5. Apply or complete the action where applicable. 6. Observe the page, messages, saved data, balances, and related records as applicable. | F18: `*` next to label | G18: TEST_CASES_Loan_Type.xlsx / TC-LT-037 | H18: TBD | I18: Not Executed | J18: Source section: B. Create (IDs: TC-LT-028–046, TC-LT-057–066 new)
A19: LME-LT-012 | B19: Item for loan interest posting required | C19: Refer to Common Preconditions above. | D19: Other required fields: Use the valid values listed below Target field: Blank Name: QA Non-Revolving Loan Type Type: Non-revolving Interest calculation method: Simple Description: Client QA loan type | E19: 1. Sign in to Sage Intacct with the test user. 2. Navigate to Applications > Lending Management > Loan type. 3. Open the page or record relevant to the scenario. 4. Perform the scenario action: Item for loan interest posting required. 5. Apply or complete the action where applicable. 6. Observe the page, messages, saved data, balances, and related records as applicable. | F19: `*` next to label | G19: TEST_CASES_Loan_Type.xlsx / TC-LT-038 | H19: TBD | I19: Not Executed | J19: Source section: B. Create (IDs: TC-LT-028–046, TC-LT-057–066 new)
... A28: LME-LT-021 | B28: **[new]** Stale Fee type value blocks save after switching row Type away from Fee | C28: Refer to Common Preconditions above. | D28: Name: QA Non-Revolving Loan Type Type: Non-revolving Interest calculation method: Simple Description: Client QA loan type | E28: 1. Sign in to Sage Intacct with the test user. 2. Navigate to Applications > Lending Management > Loan type. 3. Open the page or record relevant to the scenario. 4. Perform the scenario action: **[new]** Stale Fee type value blocks save after switching row Type away from Fee. 5. Click Save or the applicable submit action. 6. Observe the page, messages, saved data, balances, and related records as applicable. | F28: Setting a row's Type to Fee + a Fee type value, then switching Type to Interest/Principal without clearing Fee type, and saving, shows: "PRINCIPAL_OR_INTEREST_SHOULD_NOT_HAVE_ANY_FEE_SELECTED" | G28: TEST_CASES_Loan_Type.xlsx / TC-LT-066 | H28: TBD | I28: Not Executed | J28: Source section: B. Create (IDs: TC-LT-028–046, TC-LT-057–066 new)
A29: EDIT (11 test cases)
A30: LME-LT-022 | B30: Edit button visible | C30: Refer to Common Preconditions above. | D30: Name: QA Non-Revolving Loan Type Type: Non-revolving Interest calculation method: Simple Description: Client QA loan type | E30: 1. Sign in to Sage Intacct with the test user. 2. Navigate to Applications > Lending Management > Loan type. 3. Open an existing record, click Edit, and change the field(s) relevant to the scenario. 4. Perform the scenario action: Edit button visible. 5. Click Save or the applicable submit action. 6. Observe the page, messages, saved data, balances, and related records as applicable. | F30: Visible (directly in header) | G30: TEST_CASES_Loan_Type.xlsx / TC-LT-023 | H30: TBD | I30: Not Executed | J30: Source section: C. View (IDs: TC-LT-015–027)
A31: LME-LT-023 | B31: Edit form pre-populates name | C31: Refer to Common Preconditions above. | D31: Name: QA Non-Revolving Loan Type Type: Non-revolving Interest calculation method: Simple Description: Client QA loan type | E31: 1. Sign in to Sage Intacct with the test user. 2. Navigate to Applications > Lending Management > Loan type. 3. Open an existing record, click Edit, and change the field(s) relevant to the scenario. 4. Perform the scenario action: Edit form pre-populates name. 5. Click Save or the applicable submit action. 6. Observe the page, messages, saved data, balances, and related records as applicable. | F31: Pre-filled | G31: TEST_CASES_Loan_Type.xlsx / TC-LT-047 | H31: TBD | I31: Not Executed | J31: Source section: D. Edit (IDs: TC-LT-047–056)
A32: LME-LT-024 | B32: Edit form pre-populates Description | C32: Refer to Common Preconditions above. | D32: Name: QA Non-Revolving Loan Type Type: Non-revolving Interest calculation method: Simple Description: Client QA test text | E32: 1. Sign in to Sage Intacct with the test user. 2. Navigate to Applications > Lending Management > Loan type. 3. Open an existing record, click Edit, and change the field(s) relevant to the scenario. 4. Perform the scenario action: Edit form pre-populates Description. 5. Click Save or the applicable submit action. 6. Observe the page, messages, saved data, balances, and related records as applicable. | F32: Pre-filled | G32: TEST_CASES_Loan_Type.xlsx / TC-LT-048 | H32: TBD | I32: Not Executed | J32: Source section: D. Edit (IDs: TC-LT-047–056)
A33: LME-LT-025 | B33: Type is read-only in Edit | C33: Refer to Common Preconditions above. | D33: Name: QA Non-Revolving Loan Type Type: Non-revolving Interest calculation method: Simple Description: Client QA loan type | E33: 1. Sign in to Sage Intacct with the test user. 2. Navigate to Applications > Lending Management > Loan type. 3. Open an existing record, click Edit, and change the field(s) relevant to the scenario. 4. Perform the scenario action: Type is read-only in Edit. 5. Click Save or the applicable submit action. 6. Observe the page, messages, saved data, balances, and related records as applicable. | F33: Plain text, not editable dropdown/radio | G33: TEST_CASES_Loan_Type.xlsx / TC-LT-049 | H33: TBD | I33: Not Executed | J33: Source section: D. Edit (IDs: TC-LT-047–056)
A34: LME-LT-026 | B34: Edit form pre-populates Interest type | C34: Refer to Common Preconditions above. | D34: Name: QA Non-Revolving Loan Type Type: Non-revolving Interest calculation method: Simple Description: Client QA loan type | E34: 1. Sign in to Sage Intacct with the test user. 2. Navigate to Applications > Lending Management > Loan type. 3. Open an existing record, click Edit, and change the field(s) relevant to the scenario. 4. Perform the scenario action: Edit form pre-populates Interest type. 5. Click Save or the applicable submit action. 6. Observe the page, messages, saved data, balances, and related records as applicable. | F34: Shown | G34: TEST_CASES_Loan_Type.xlsx / TC-LT-050 | H34: TBD | I34: Not Executed | J34: Source section: D. Edit (IDs: TC-LT-047–056)
A35: LME-LT-027 | B35: Edit form pre-populates Interest calculation method | C35: Refer to Common Preconditions above. | D35: Name: QA Non-Revolving Loan Type Type: Non-revolving Interest calculation method: Simple Description: Client QA loan type | E35: 1. Sign in to Sage Intacct with the test user. 2. Navigate to Applications > Lending Management > Loan type. 3. Open an existing record, click Edit, and change the field(s) relevant to the scenario. 4. Perform the scenario action: Edit form pre-populates Interest calculation method. 5. Click Save or the applicable submit action. 6. Observe the page, messages, saved data, balances, and related records as applicable. | F35: Shown | G35: TEST_CASES_Loan_Type.xlsx / TC-LT-051 | H35: TBD | I35: Not Executed | J35: Source section: D. Edit (IDs: TC-LT-047–056)
A36: LME-LT-028 | B36: Edit form pre-populates Status | C36: Refer to Common Preconditions above. | D36: Name: QA Non-Revolving Loan Type Type: Non-revolving Interest calculation method: Simple Description: Client QA loan type | E36: 1. Sign in to Sage Intacct with the test user. 2. Navigate to Applications > Lending Management > Loan type. 3. Open an existing record, click Edit, and change the field(s) relevant to the scenario. 4. Perform the scenario action: Edit form pre-populates Status. 5. Click Save or the applicable submit action. 6. Observe the page, messages, saved data, balances, and related records as applicable. | F36: Shown ('Active') | G36: TEST_CASES_Loan_Type.xlsx / TC-LT-052 | H36: TBD | I36: Not Executed | J36: Source section: D. Edit (IDs: TC-LT-047–056)
